Workbook

Sheet CutPoints
E1: 100 | F1: 2024 Pub CutPoints | J1: 2025 Pub CutPoints | N1: 2026 Pub CutPoints | R1: 2027 Pub CutPoints (Derived)
A2: Measure ID | B2: Measure Name | C2: Domain | D2: Weight | E2: Trend Ind | F2: 5-Star | G2: 4-Star | H2: 3-Star | I2: 2-Star | J2: 5-Star | K2: 4-Star | L2: 3-Star | M2: 2-Star | N2: 5-Star | O2: 4-Star | P2: 3-Star | Q2: 2-Star | R2: 5-Star | S2: 4-Star | T2: 3-Star | U2: 2-Star
A3: 999901 | B3: Annual Flu Vaccine | C3: CAHPS | D3: 1 | E3: H | F3: 0.78 | G3: 0.74 | H3: 0.67 | I3: 0.63 | J3: 0.76 | K3: 0.71 | L3: 0.65 | M3: 0.61 | N3: 0.73 | O3: 0.68 | P3: 0.61 | Q3: 0.57 | R3: =ROUND(AVERAGE(F3,J3,N3),2) -> 0.76 | S3: =ROUND(AVERAGE(G3,K3,O3),2) -> 0.71 | T3: =ROUND(AVERAGE(H3,L3,P3),2) -> 0.64 | U3: =ROUND(AVERAGE(I3,M3,Q3),2) -> 0.6
A4: 999922 | B4: Care Coordination | C4: CAHPS | D4: 2 | E4: H | F4: 0.87 | G4: 0.86 | H4: 0.84 | I4: 0.83 | J4: 0.88 | K4: 0.87 | L4: 0.85 | M4: 0.84 | N4: 0.89 | O4: 0.88 | P4: 0.86 | Q4: 0.85 | R4: =ROUND(AVERAGE(F4,J4,N4),2) + 0.02 -> 0.9 | S4: =ROUND(AVERAGE(G4,K4,O4),2) -> 0.87 | T4: =ROUND(AVERAGE(H4,L4,P4),2) -> 0.85 | U4: =ROUND(AVERAGE(I4,M4,Q4),2) -> 0.84
A5: 999913 | B5: Customer Service | C5: CAHPS | D5: 2 | E5: H | F5: 0.92 | G5: 0.9 | H5: 0.89 | I5: 0.88 | J5: 0.92 | K5: 0.91 | L5: 0.89 | M5: 0.88 | N5: 0.92 | O5: 0.91 | P5: 0.89 | Q5: 0.88 | R5: =ROUND(AVERAGE(F5,J5,N5),2) -> 0.92 | S5: =ROUND(AVERAGE(G5,K5,O5),2) -> 0.91 | T5: =ROUND(AVERAGE(H5,L5,P5),2) -> 0.89 | U5: =ROUND(AVERAGE(I5,M5,Q5),2) -> 0.88
A6: 999912 | B6: Getting Appointments and Care Quickly | C6: CAHPS | D6: 2 | E6: H | F6: 0.8 | G6: 0.78 | H6: 0.76 | I6: 0.74 | J6: 0.86 | K6: 0.84 | L6: 0.82 | M6: 0.8 | N6: 0.86 | O6: 0.84 | P6: 0.82 | Q6: 0.8 | R6: =ROUND(AVERAGE(F6,J6,N6),2) -> 0.84 | S6: =ROUND(AVERAGE(G6,K6,O6),2) -> 0.82 | T6: =ROUND(AVERAGE(H6,L6,P6),2) -> 0.8 | U6: =ROUND(AVERAGE(I6,M6,Q6),2) -> 0.78
A7: 999911 | B7: Getting Needed Care | C7: CAHPS | D7: 2 | E7: H | F7: 0.83 | G7: 0.81 | H7: 0.78 | I7: 0.76 | J7: 0.83 | K7: 0.82 | L7: 0.79 | M7: 0.77 | N7: 0.84 | O7: 0.82 | P7: 0.8 | Q7: 0.78 | R7: =ROUND(AVERAGE(F7,J7,N7),2) -> 0.83 | S7: =ROUND(AVERAGE(G7,K7,O7),2) -> 0.82 | T7: =ROUND(AVERAGE(H7,L7,P7),2) -> 0.79 | U7: =ROUND(AVERAGE(I7,M7,Q7),2) -> 0.77
A8: 999811 | B8: Getting Needed Prescription Drugs | C8: CAHPS | D8: 2 | E8: H | F8: 0.91 | G8: 0.9 | H8: 0.89 | I8: 0.87 | J8: 0.91 | K8: 0.9 | L8: 0.88 | M8: 0.87 | N8: 0.91 | O8: 0.9 | P8: 0.88 | Q8: 0.87 | R8: =ROUND(AVERAGE(F8,J8,N8),2) -> 0.91 | S8: =ROUND(AVERAGE(G8,K8,O8),2) -> 0.9 | T8: =ROUND(AVERAGE(H8,L8,P8),2) -> 0.88 | U8: =ROUND(AVERAGE(I8,M8,Q8),2) -> 0.87
A9: 999810 | B9: Rating of Drug Plan | C9: CAHPS | D9: 2 | E9: H | F9: 0.89 | G9: 0.87 | H9: 0.85 | I9: 0.84 | J9: 0.89 | K9: 0.87 | L9: 0.86 | M9: 0.84 | N9: 0.89 | O9: 0.88 | P9: 0.86 | Q9: 0.85 | R9: =ROUND(AVERAGE(F9,J9,N9),2) -> 0.89 | S9: =ROUND(AVERAGE(G9,K9,O9),2) -> 0.87 | T9: =ROUND(AVERAGE(H9,L9,P9),2) -> 0.86 | U9: =ROUND(AVERAGE(I9,M9,Q9),2) -> 0.84
A10: 999914 | B10: Rating of Health Care Quality | C10: CAHPS | D10: 2 | E10: H | F10: 0.88 | G10: 0.87 | H10: 0.85 | I10: 0.84 | J10: 0.88 | K10: 0.87 | L10: 0.85 | M10: 0.84 | N10: 0.88 | O10: 0.87 | P10: 0.86 | Q10: 0.84 | R10: =ROUND(AVERAGE(F10,J10,N10),2) -> 0.88 | S10: =ROUND(AVERAGE(G10,K10,O10),2) -> 0.87 | T10: =ROUND(AVERAGE(H10,L10,P10),2) -> 0.85 | U10: =ROUND(AVERAGE(I10,M10,Q10),2) -> 0.84
A11: 999915 | B11: Rating of Health Plan | C11: CAHPS | D11: 2 | E11: H | F11: 0.89 | G11: 0.88 | H11: 0.85 | I11: 0.84 | J11: 0.89 | K11: 0.88 | L11: 0.86 | M11: 0.84 | N11: 0.89 | O11: 0.87 | P11: 0.85 | Q11: 0.84 | R11: =ROUND(AVERAGE(F11,J11,N11),2) -> 0.89 | S11: =ROUND(AVERAGE(G11,K11,O11),2) -> 0.88 | T11: =ROUND(AVERAGE(H11,L11,P11),2) -> 0.85 | U11: =ROUND(AVERAGE(I11,M11,Q11),2) -> 0.84
A12: 909230 | B12: Breast Cancer Screening | C12: HEDIS | D12: 1 | E12: H | F12: 0.79 | G12: 0.71 | H12: 0.63 | I12: 0.48 | J12: 0.82 | K12: 0.75 | L12: 0.67 | M12: 0.53 | N12: 0.84 | O12: 0.76 | P12: 0.71 | Q12: 0.58 | R12: =ROUND(AVERAGE(F12,J12,N12),2) -> 0.82 | S12: =ROUND(AVERAGE(G12,K12,O12),2) -> 0.74 | T12: =ROUND(AVERAGE(H12,L12,P12),2) -> 0.67 | U12: =ROUND(AVERAGE(I12,M12,Q12),2) -> 0.53
A13: 107125 | B13: Care for Older Adults - Medication Review | C13: HEDIS | D13: 1 | E13: H | F13: 0.98 | G13: 0.87 | H13: 0.75 | I13: 0.48 | J13: 0.98 | K13: 0.92 | L13: 0.8 | M13: 0.53 | N13: 0.98 | O13: 0.93 | P13: 0.85 | Q13: 0.58 | R13: =ROUND(AVERAGE(F13,J13,N13),2) -> 0.98 | S13: =ROUND(AVERAGE(G13,K13,O13),2) -> 0.91 | T13: =ROUND(AVERAGE(H13,L13,P13),2) -> 0.8 | U13: =ROUND(AVERAGE(I13,M13,Q13),2) -> 0.53
A14: 107126 | B14: Care for Older Adults - Functional Status Assessment | C14: HEDIS | D14: 1 | E14: H | F14: 0.94 | G14: 0.8 | H14: 0.66 | I14: 0.48 | J14: 0.91 | K14: 0.78 | L14: 0.66 | M14: 0.46 | N14: 0.95 | O14: 0.82 | P14: 0.68 | Q14: 0.5 | R14: =ROUND(AVERAGE(F14,J14,N14),2) -> 0.93 | S14: =ROUND(AVERAGE(G14,K14,O14),2) -> 0.8 | T14: =ROUND(AVERAGE(H14,L14,P14),2) -> 0.67 | U14: =ROUND(AVERAGE(I14,M14,Q14),2) -> 0.48
A15: 107127 | B15: Care for Older Adults - Pain Assessment | C15: HEDIS | D15: 1 | E15: H | F15: 0.96 | G15: 0.9 | H15: 0.76 | I15: 0.55 | J15: 0.96 | K15: 0.92 | L15: 0.81 | M15: 0.6 | N15: 0.99 | O15: 0.95 | P15: 0.86 | Q15: 0.65 | R15: =ROUND(AVERAGE(F15,J15,N15),2) -> 0.97 | S15: =ROUND(AVERAGE(G15,K15,O15),2) -> 0.92 | T15: =ROUND(AVERAGE(H15,L15,P15),2) -> 0.81 | U15: =ROUND(AVERAGE(I15,M15,Q15),2) -> 0.6
A16: 600452 | B16: Colorectal Cancer Screening | C16: HEDIS | D16: 1 | E16: H | F16: 0.8 | G16: 0.71 | H16: 0.6 | I16: 0.48 | J16: 0.83 | K16: 0.75 | L16: 0.65 | M16: 0.53 | N16: 0.78 | O16: 0.7 | P16: 0.6 | Q16: 0.48 | R16: =ROUND(AVERAGE(F16,J16,N16),2) -> 0.8 | S16: =ROUND(AVERAGE(G16,K16,O16),2) -> 0.72 | T16: =ROUND(AVERAGE(H16,L16,P16),2) -> 0.62 | U16: =ROUND(AVERAGE(I16,M16,Q16),2) -> 0.5
... A47: 201185 | B47: Polypharmacy: Use of Multiple Anticholinergic Medications in Older Adults | C47: PatientSafety | D47: 1 | E47: L | F47: 0.06 | G47: 0.09 | H47: 0.11 | I47: 0.17 | J47: 0.06 | K47: 0.08 | L47: 0.1 | M47: 0.14 | N47: 0.05 | O47: 0.07 | P47: 0.1 | Q47: 0.16 | R47: =ROUND(AVERAGE(F47,J47,N47),2) -> 0.06 | S47: =ROUND(AVERAGE(G47,K47,O47),2) -> 0.08 | T47: =ROUND(AVERAGE(H47,L47,P47),2) -> 0.1 | U47: =ROUND(AVERAGE(I47,M47,Q47),2) -> 0.16
A48: 999813 | B48: Drug Plan Quality Improvement | C48: QI | D48: 5 | E48: H | F48: 0.456458 | G48: 0.206957 | H48: 0 | I48: -0.253472 | J48: 0.496603 | K48: 0.242468 | L48: 0 | M48: -0.218869 | N48: 0.579545 | O48: 0.320439 | P48: 0 | Q48: -0.233766 | R48: =ROUND(AVERAGE(F48,J48,N48),6) -> 0.510869 | S48: =ROUND(AVERAGE(G48,K48,O48),6) -> 0.256621 | T48: =ROUND(AVERAGE(H48,L48,P48),6) -> 0 | U48: =ROUND(AVERAGE(I48,M48,Q48),6) -> -0.235369
A49: 999923 | B49: Health Plan Quality Improvement | C49: QI | D49: 5 | E49: H | F49: 0.385631 | G49: 0.190622 | H49: 0 | I49: -0.262671 | J49: 0.421057 | K49: 0.174445 | L49: 0 | M49: -0.179809 | N49: 0.391253 | O49: 0.202884 | P49: 0 | Q49: -0.121368 | R49: =ROUND(AVERAGE(F49,J49,N49),6) -> 0.399314 | S49: =ROUND(AVERAGE(G49,K49,O49),6) -> 0.189317 | T49: =ROUND(AVERAGE(H49,L49,P49),6) -> 0 | U49: =ROUND(AVERAGE(I49,M49,Q49),6) -> -0.187949
A50: 108009 | B50: Plan All-Cause Readmissions | C50: ReAdmits | D50: 3 | E50: L | F50: 0.08 | G50: 0.1 | H50: 0.11 | I50: 0.13 | J50: 0.08 | K50: 0.1 | L50: 0.12 | M50: 0.14 | N50: 0.07 | O50: 0.09 | P50: 0.1 | Q50: 0.12 | R50: =ROUND(AVERAGE(F50,J50,N50),2) -> 0.08 | S50: =ROUND(AVERAGE(G50,K50,O50),2) -> 0.1 | T50: =ROUND(AVERAGE(H50,L50,P50),2) -> 0.11 | U50: =ROUND(AVERAGE(I50,M50,Q50),2) -> 0.13

Sheet Data for Analysis
A1: CMID | B1: Contract | C1: Measure ID | D1: Measure Name | E1: Weight | F1: Domian | G1: Trend | H1: Cutpoint 5 | I1: Cutpoint 4 | J1: Cutpoint 3 | K1: Cutpoint 2 | L1: Num | M1: Denom | N1: Adjust Prob | O1: Forecast Rate | P1: Forecast Star | Q1: Min Threshold | R1: SRF Rate Previous Year | S1: DENOM Previous Year | T1: SRF Rate Current year | U1: Denom Current year | V1: HEI Upper Band | W1: HEI Lower Band | X1: HEI Score | Y1: LOG Odds | Z1: Contract Specific Propotion | AA1: Contract Unadjusted Rate | AB1: LOG | AC1: Exponent | AD1: Rate as per CMS | AE1: Weighted Numerator | AF1: Weighted Denom
A2: =B2&C2 -> H0123999810 | B2: H0123 | C2: 999810 | D2: D05: Rating of Drug Plan | E2: 2 | F2: CAHPS | G2: H | H2: =VLOOKUP($C2,CutPoints!$A:$U,18,0) -> 0.89 | I2: =VLOOKUP($C2,CutPoints!$A:$U,19,0) -> 0.87 | J2: =VLOOKUP($C2,CutPoints!$A:$U,20,0) -> 0.86 | K2: =VLOOKUP($C2,CutPoints!$A:$U,21,0) -> 0.84 | O2: 0.82 | P2: =IF($G2="H",IF(ROUND(O2,2)>=H2,5,IF(ROUND(O2,2)>=I2,4,IF(ROUND(O2,2)>=J2,3,IF(ROUND(O2,2)>=K2,2,1)))),IF(ROUND(O2,2)<=H2,5,IF(ROUND(O2,2)<=I2,4,IF(ROUND(O2,2)<=J2,3,IF(ROUND(O2,2)<=K2,2,1))))) -> 1 | Q2: =IFERROR(VLOOKUP(C2,Thresholds!A:C,3,0), "") | R2: =IFERROR(VLOOKUP($C2,Synthetic!$A:$M,3,0),"") -> 0.842 | S2: =IFERROR(VLOOKUP($C2,Synthetic!$A:$M,6,0),"") -> 400 | T2: =IFERROR(VLOOKUP($C2,Synthetic!$A:$M,4,0),"") -> 0.848 | U2: =IFERROR(VLOOKUP($C2,Synthetic!$A:$M,7,0),"") -> 430 | V2: =IFERROR(VLOOKUP($C2,Synthetic!$A:$M,9,0),"") -> 0.89765 | W2: =IFERROR(VLOOKUP($C2,Synthetic!$A:$M,10,0),"") -> 0.87657 | X2: =IF(AD2>V2,1,IF(AD2>W2,0,-1)) -> 1 | Y2: =IFERROR(VLOOKUP($C2,Synthetic!$A:$M,12,0),"") -> 0.9323 | Z2: =U2/(U2+S2) -> 0.51807229 | AA2: =(U2*T2+S2*R2)/(U2+S2) -> 0.84510843 | AB2: =LN(AA2/(1-AA2)) -> 1.6967396 | AC2: =EXP(AB2+Y2*Z2) -> 8.8439927 | AD2: =AC2/(1+AC2) -> 0.8984152 | AE2: =IFERROR(X2*E2,0) -> 2 | AF2: =IF(AE2=0,0,E2) -> 2
A3: =B3&C3 -> H0123999811 | B3: H0123 | C3: 999811 | D3: D06: Getting Needed Prescription Drugs | E3: 2 | F3: CAHPS | G3: H | H3: =VLOOKUP($C3,CutPoints!$A:$U,18,0) -> 0.91 | I3: =VLOOKUP($C3,CutPoints!$A:$U,19,0) -> 0.9 | J3: =VLOOKUP($C3,CutPoints!$A:$U,20,0) -> 0.88 | K3: =VLOOKUP($C3,CutPoints!$A:$U,21,0) -> 0.87 | O3: 0.89 | P3: =IF($G3="H",IF(ROUND(O3,2)>=H3,5,IF(ROUND(O3,2)>=I3,4,IF(ROUND(O3,2)>=J3,3,IF(ROUND(O3,2)>=K3,2,1)))),IF(ROUND(O3,2)<=H3,5,IF(ROUND(O3,2)<=I3,4,IF(ROUND(O3,2)<=J3,3,IF(ROUND(O3,2)<=K3,2,1))))) -> 3 | Q3: =IFERROR(VLOOKUP(C3,Thresholds!A:C,3,0), "") | R3: =IFERROR(VLOOKUP($C3,Synthetic!$A:$M,3,0),"") -> 0.11228143 | S3: =IFERROR(VLOOKUP($C3,Synthetic!$A:$M,6,0),"") -> 251 | T3: =IFERROR(VLOOKUP($C3,Synthetic!$A:$M,4,0),"") -> 0.51974656 | U3: =IFERROR(VLOOKUP($C3,Synthetic!$A:$M,7,0),"") -> 437 | V3: =IFERROR(VLOOKUP($C3,Synthetic!$A:$M,9,0),"") -> 0.022320152 | W3: =IFERROR(VLOOKUP($C3,Synthetic!$A:$M,10,0),"") -> 0.011090152 | X3: 1 | Y3: =IFERROR(VLOOKUP($C3,Synthetic!$A:$M,12,0),"") -> 0.70906829 | Z3: =U3/(U3+S3) -> 0.63517442 | AA3: =(U3*T3+S3*R3)/(U3+S3) -> 0.37109286 | AB3: =LN(AA3/(1-AA3)) -> -0.5275313 | AC3: =EXP(AB3+Y3*Z3) -> 0.92575166 | AD3: =AC3/(1+AC3) -> 0.48072225 | AE3: =IFERROR(X3*E3,0) -> 2 | AF3: =IF(AE3=0,0,E3) -> 2
A4: =B4&C4 -> H0123999901 | B4: H0123 | C4: 999901 | D4: C03: Annual Flu Vaccine | E4: 1 | F4: CAHPS | G4: H | H4: =VLOOKUP($C4,CutPoints!$A:$U,18,0) -> 0.76 | I4: =VLOOKUP($C4,CutPoints!$A:$U,19,0) -> 0.71 | J4: =VLOOKUP($C4,CutPoints!$A:$U,20,0) -> 0.64 | K4: =VLOOKUP($C4,CutPoints!$A:$U,21,0) -> 0.6 | O4: 0.61 | P4: =IF($G4="H",IF(ROUND(O4,2)>=H4,5,IF(ROUND(O4,2)>=I4,4,IF(ROUND(O4,2)>=J4,3,IF(ROUND(O4,2)>=K4,2,1)))),IF(ROUND(O4,2)<=H4,5,IF(ROUND(O4,2)<=I4,4,IF(ROUND(O4,2)<=J4,3,IF(ROUND(O4,2)<=K4,2,1))))) -> 2 | Q4: =IFERROR(VLOOKUP(C4,Thresholds!A:C,3,0), "") | R4: =IFERROR(VLOOKUP($C4,Synthetic!$A:$M,3,0),"") -> 0.015265875 | S4: =IFERROR(VLOOKUP($C4,Synthetic!$A:$M,6,0),"") -> 342 | T4: =IFERROR(VLOOKUP($C4,Synthetic!$A:$M,4,0),"") -> 0.23074255 | U4: =IFERROR(VLOOKUP($C4,Synthetic!$A:$M,7,0),"") -> 484 | V4: =IFERROR(VLOOKUP($C4,Synthetic!$A:$M,9,0),"") -> 0.65279442 | W4: =IFERROR(VLOOKUP($C4,Synthetic!$A:$M,10,0),"") -> 0.64156442 | X4: =IF(AD4>V4,1,IF(AD4>W4,0,-1)) -> -1 | Y4: =IFERROR(VLOOKUP($C4,Synthetic!$A:$M,12,0),"") -> 0.73038471 | Z4: =U4/(U4+S4) -> 0.58595642 | AA4: =(U4*T4+S4*R4)/(U4+S4) -> 0.14152581 | AB4: =LN(AA4/(1-AA4)) -> -1.8026745 | AC4: =EXP(AB4+Y4*Z4) -> 0.25291524 | AD4: =AC4/(1+AC4) -> 0.20186141 | AE4: =IFERROR(X4*E4,0) -> -1 | AF4: =IF(AE4=0,0,E4) -> 1
A5: =B5&C5 -> H0123999911 | B5: H0123 | C5: 999911 | D5: C22: Getting Needed Care | E5: 2 | F5: CAHPS | G5: H | H5: =VLOOKUP($C5,CutPoints!$A:$U,18,0) -> 0.83 | I5: =VLOOKUP($C5,CutPoints!$A:$U,19,0) -> 0.82 | J5: =VLOOKUP($C5,CutPoints!$A:$U,20,0) -> 0.79 | K5: =VLOOKUP($C5,CutPoints!$A:$U,21,0) -> 0.77 | O5: 0.83 | P5: =IF($G5="H",IF(ROUND(O5,2)>=H5,5,IF(ROUND(O5,2)>=I5,4,IF(ROUND(O5,2)>=J5,3,IF(ROUND(O5,2)>=K5,2,1)))),IF(ROUND(O5,2)<=H5,5,IF(ROUND(O5,2)<=I5,4,IF(ROUND(O5,2)<=J5,3,IF(ROUND(O5,2)<=K5,2,1))))) -> 5 | Q5: =IFERROR(VLOOKUP(C5,Thresholds!A:C,3,0), "") | R5: =IFERROR(VLOOKUP($C5,Synthetic!$A:$M,3,0),"") -> 0.95874412 | S5: =IFERROR(VLOOKUP($C5,Synthetic!$A:$M,6,0),"") -> 224 | T5: =IFERROR(VLOOKUP($C5,Synthetic!$A:$M,4,0),"") -> 0.61110454 | U5: =IFERROR(VLOOKUP($C5,Synthetic!$A:$M,7,0),"") -> 430 | V5: =IFERROR(VLOOKUP($C5,Synthetic!$A:$M,9,0),"") -> 0.27857366 | W5: =IFERROR(VLOOKUP($C5,Synthetic!$A:$M,10,0),"") -> 0.26734366 | X5: =IF(AD5>V5,1,IF(AD5>W5,0,-1)) -> 1 | Y5: =IFERROR(VLOOKUP($C5,Synthetic!$A:$M,12,0),"") -> 0.38813083 | Z5: =U5/(U5+S5) -> 0.65749235 | AA5: =(U5*T5+S5*R5)/(U5+S5) -> 0.73017375 | AB5: =LN(AA5/(1-AA5)) -> 0.99550429 | AC5: =EXP(AB5+Y5*Z5) -> 3.4927778 | AD5: =AC5/(1+AC5) -> 0.77742055 | AE5: =IFERROR(X5*E5,0) -> 2 | AF5: =IF(AE5=0,0,E5) -> 2
A6: =B6&C6 -> H0123999912 | B6: H0123 | C6: 999912 | D6: C23: Getting Appointments and Care Quickly | E6: 2 | F6: CAHPS | G6: H | H6: =VLOOKUP($C6,CutPoints!$A:$U,18,0) -> 0.84 | I6: =VLOOKUP($C6,CutPoints!$A:$U,19,0) -> 0.82 | J6: =VLOOKUP($C6,CutPoints!$A:$U,20,0) -> 0.8 | K6: =VLOOKUP($C6,CutPoints!$A:$U,21,0) -> 0.78 | O6: 0.91 | P6: =IF($G6="H",IF(ROUND(O6,2)>=H6,5,IF(ROUND(O6,2)>=I6,4,IF(ROUND(O6,2)>=J6,3,IF(ROUND(O6,2)>=K6,2,1)))),IF(ROUND(O6,2)<=H6,5,IF(ROUND(O6,2)<=I6,4,IF(ROUND(O6,2)<=J6,3,IF(ROUND(O6,2)<=K6,2,1))))) -> 5 | Q6: =IFERROR(VLOOKUP(C6,Thresholds!A:C,3,0), "") | R6: =IFERROR(VLOOKUP($C6,Synthetic!$A:$M,3,0),"") | AE6: =IFERROR(X6*E6,0) -> 0 | AF6: =IF(AE6=0,0,E6) -> 0
A7: =B7&C7 -> H0123999913 | B7: H0123 | C7: 999913 | D7: C24: Customer Service | E7: 2 | F7: CAHPS | G7: H | H7: =VLOOKUP($C7,CutPoints!$A:$U,18,0) -> 0.92 | I7: =VLOOKUP($C7,CutPoints!$A:$U,19,0) -> 0.91 | J7: =VLOOKUP($C7,CutPoints!$A:$U,20,0) -> 0.89 | K7: =VLOOKUP($C7,CutPoints!$A:$U,21,0) -> 0.88 | O7: 0.9 | P7: =IF($G7="H",IF(ROUND(O7,2)>=H7,5,IF(ROUND(O7,2)>=I7,4,IF(ROUND(O7,2)>=J7,3,IF(ROUND(O7,2)>=K7,2,1)))),IF(ROUND(O7,2)<=H7,5,IF(ROUND(O7,2)<=I7,4,IF(ROUND(O7,2)<=J7,3,IF(ROUND(O7,2)<=K7,2,1))))) -> 3 | Q7: =IFERROR(VLOOKUP(C7,Thresholds!A:C,3,0), "") | R7: =IFERROR(VLOOKUP($C7,Synthetic!$A:$M,3,0),"") | AE7: =IFERROR(X7*E7,0) -> 0 | AF7: =IF(AE7=0,0,E7) -> 0
A8: =B8&C8 -> H0123999914 | B8: H0123 | C8: 999914 | D8: C25: Rating of Health Care Quality | E8: 2 | F8: CAHPS | G8: H | H8: =VLOOKUP($C8,CutPoints!$A:$U,18,0) -> 0.88 | I8: =VLOOKUP($C8,CutPoints!$A:$U,19,0) -> 0.87 | J8: =VLOOKUP($C8,CutPoints!$A:$U,20,0) -> 0.85 | K8: =VLOOKUP($C8,CutPoints!$A:$U,21,0) -> 0.84 | O8: 0.88 | P8: =IF($G8="H",IF(ROUND(O8,2)>=H8,5,IF(ROUND(O8,2)>=I8,4,IF(ROUND(O8,2)>=J8,3,IF(ROUND(O8,2)>=K8,2,1)))),IF(ROUND(O8,2)<=H8,5,IF(ROUND(O8,2)<=I8,4,IF(ROUND(O8,2)<=J8,3,IF(ROUND(O8,2)<=K8,2,1))))) -> 5 | Q8: =IFERROR(VLOOKUP(C8,Thresholds!A:C,3,0), "") | R8: =IFERROR(VLOOKUP($C8,Synthetic!$A:$M,3,0),"") | AE8: =IFERROR(X8*E8,0) -> 0 | AF8: =IF(AE8=0,0,E8) -> 0
A9: =B9&C9 -> H0123999915 | B9: H0123 | C9: 999915 | D9: C26: Rating of Health Plan | E9: 2 | F9: CAHPS | G9: H | H9: =VLOOKUP($C9,CutPoints!$A:$U,18,0) -> 0.89 | I9: =VLOOKUP($C9,CutPoints!$A:$U,19,0) -> 0.88 | J9: =VLOOKUP($C9,CutPoints!$A:$U,20,0) -> 0.85 | K9: =VLOOKUP($C9,CutPoints!$A:$U,21,0) -> 0.84 | O9: 0.86 | P9: =IF($G9="H",IF(ROUND(O9,2)>=H9,5,IF(ROUND(O9,2)>=I9,4,IF(ROUND(O9,2)>=J9,3,IF(ROUND(O9,2)>=K9,2,1)))),IF(ROUND(O9,2)<=H9,5,IF(ROUND(O9,2)<=I9,4,IF(ROUND(O9,2)<=J9,3,IF(ROUND(O9,2)<=K9,2,1))))) -> 3 | Q9: =IFERROR(VLOOKUP(C9,Thresholds!A:C,3,0), "") | R9: =IFERROR(VLOOKUP($C9,Synthetic!$A:$M,3,0),"") -> 0.4982027 | S9: =IFERROR(VLOOKUP($C9,Synthetic!$A:$M,6,0),"") -> 259 | T9: =IFERROR(VLOOKUP($C9,Synthetic!$A:$M,4,0),"") -> 0.62447198 | U9: =IFERROR(VLOOKUP($C9,Synthetic!$A:$M,7,0),"") -> 494 | V9: =IFERROR(VLOOKUP($C9,Synthetic!$A:$M,9,0),"") -> 0.53052463 | W9: =IFERROR(VLOOKUP($C9,Synthetic!$A:$M,10,0),"") -> 0.51929463 | X9: =IF(AD9>V9,1,IF(AD9>W9,0,-1)) -> 1 | Y9: =IFERROR(VLOOKUP($C9,Synthetic!$A:$M,12,0),"") -> 0.66290993 | Z9: =U9/(U9+S9) -> 0.6560425 | AA9: =(U9*T9+S9*R9)/(U9+S9) -> 0.58104071 | AB9: =LN(AA9/(1-AA9)) -> 0.32704708 | AC9: =EXP(AB9+Y9*Z9) -> 2.1424374 | AD9: =AC9/(1+AC9) -> 0.68177568 | AE9: =IFERROR(X9*E9,0) -> 2 | AF9: =IF(AE9=0,0,E9) -> 2
A10: =B10&C10 -> H0123999922 | B10: H0123 | C10: 999922 | D10: C27: Care Coordination | E10: 2 | F10: CAHPS | G10: H | H10: =VLOOKUP($C10,CutPoints!$A:$U,18,0) -> 0.9 | I10: =VLOOKUP($C10,CutPoints!$A:$U,19,0) -> 0.87 | J10: =VLOOKUP($C10,CutPoints!$A:$U,20,0) -> 0.85 | K10: =VLOOKUP($C10,CutPoints!$A:$U,21,0) -> 0.84 | O10: 0.87 | P10: =IF($G10="H",IF(ROUND(O10,2)>=H10,5,IF(ROUND(O10,2)>=I10,4,IF(ROUND(O10,2)>=J10,3,IF(ROUND(O10,2)>=K10,2,1)))),IF(ROUND(O10,2)<=H10,5,IF(ROUND(O10,2)<=I10,4,IF(ROUND(O10,2)<=J10,3,IF(ROUND(O10,2)<=K10,2,1))))) -> 4 | Q10: =IFERROR(VLOOKUP(C10,Thresholds!A:C,3,0), "") | R10: =IFERROR(VLOOKUP($C10,Synthetic!$A:$M,3,0),"") -> 0.89561684 | S10: =IFERROR(VLOOKUP($C10,Synthetic!$A:$M,6,0),"") -> 259 | T10: =IFERROR(VLOOKUP($C10,Synthetic!$A:$M,4,0),"") -> 0.16113844 | U10: =IFERROR(VLOOKUP($C10,Synthetic!$A:$M,7,0),"") -> 439 | V10: =IFERROR(VLOOKUP($C10,Synthetic!$A:$M,9,0),"") -> 0.7609 | W10: =IFERROR(VLOOKUP($C10,Synthetic!$A:$M,10,0),"") -> 0.72342 | X10: =IF(AD10>V10,1,IF(AD10>W10,0,-1)) -> -1 | Y10: 0.37 | Z10: =U10/(U10+S10) -> 0.62893983 | AA10: =(U10*T10+S10*R10)/(U10+S10) -> 0.43367412 | AB10: =LN(AA10/(1-AA10)) -> -0.26687629 | AC10: =EXP(AB10+Y10*Z10) -> 0.9664086 | AD10: =AC10/(1+AC10) -> 0.49145869 | AE10: 2 | AF10: =IF(AE10=0,0,E10) -> 2
A11: =B11&C11 -> H0123101803 | B11: H0123 | C11: 101803 | D11: C14: Controlling High Blood Pressure | E11: 3 | F11: HEDIS | G11: H | H11: =VLOOKUP($C11,CutPoints!$A:$U,18,0) -> 0.84 | I11: =VLOOKUP($C11,CutPoints!$A:$U,19,0) -> 0.78 | J11: =VLOOKUP($C11,CutPoints!$A:$U,20,0) -> 0.72 | K11: =VLOOKUP($C11,CutPoints!$A:$U,21,0) -> 0.65 | L11: 650 | M11: 812 | O11: =L11/M11 -> 0.80049261 | P11: =IF(M11>=Q11, IF($G11="H",IF(ROUND(O11,2)>=H11,5,IF(ROUND(O11,2)>=I11,4,IF(ROUND(O11,2)>=J11,3,IF(ROUND(O11,2)>=K11,2,1)))),IF(ROUND(O11,2)<=H11,5,IF(ROUND(O11,2)<=I11,4,IF(ROUND(O11,2)<=J11,3,IF(ROUND(O11,2)<=K11,2,1))))), "NR") -> 4 | Q11: =IFERROR(VLOOKUP(C11,Thresholds!A:C,3,0), "") -> 30 | R11: =IFERROR(VLOOKUP($C11,Synthetic!$A:$M,3,0),"") -> 0.26478043 | S11: =IFERROR(VLOOKUP($C11,Synthetic!$A:$M,6,0),"") -> 305 | T11: =IFERROR(VLOOKUP($C11,Synthetic!$A:$M,4,0),"") -> 0.7029064 | U11: =IFERROR(VLOOKUP($C11,Synthetic!$A:$M,7,0),"") -> 402 | V11: =IFERROR(VLOOKUP($C11,Synthetic!$A:$M,9,0),"") -> 0.52002983 | W11: =IFERROR(VLOOKUP($C11,Synthetic!$A:$M,10,0),"") -> 0.50879983 | X11: =IF(AD11>V11,1,IF(AD11>W11,0,-1)) -> 1 | Y11: =IFERROR(VLOOKUP($C11,Synthetic!$A:$M,12,0),"") -> 0.62742444 | Z11: =U11/(U11+S11) -> 0.56859972 | AA11: =(U11*T11+S11*R11)/(U11+S11) -> 0.51389874 | AB11: =LN(AA11/(1-AA11)) -> 0.055609273 | AC11: =EXP(AB11+Y11*Z11) -> 1.5103821 | AD11: =AC11/(1+AC11) -> 0.60165426 | AE11: =IFERROR(X11*E11,0) -> 3 | AF11: =IF(AE11=0,0,E11) -> 3
A12: =B12&C12 -> H0123104201 | B12: H0123 | C12: 104201 | D12: C10: Osteoporosis Management in Women who had a Fracture | E12: 1 | F12: HEDIS | G12: H | H12: =VLOOKUP($C12,CutPoints!$A:$U,18,0) -> 0.69 | I12: =VLOOKUP($C12,CutPoints!$A:$U,19,0) -> 0.52 | J12: =VLOOKUP($C12,CutPoints!$A:$U,20,0) -> 0.4 | K12: =VLOOKUP($C12,CutPoints!$A:$U,21,0) -> 0.29 | L12: 247 | M12: 747 | O12: =L12/M12 -> 0.33065596 | P12: =IF(M12>=Q12, IF($G12="H",IF(ROUND(O12,2)>=H12,5,IF(ROUND(O12,2)>=I12,4,IF(ROUND(O12,2)>=J12,3,IF(ROUND(O12,2)>=K12,2,1)))),IF(ROUND(O12,2)<=H12,5,IF(ROUND(O12,2)<=I12,4,IF(ROUND(O12,2)<=J12,3,IF(ROUND(O12,2)<=K12,2,1))))), "NR") -> 2 | Q12: =IFERROR(VLOOKUP(C12,Thresholds!A:C,3,0), "") -> 30 | R12: =IFERROR(VLOOKUP($C12,Synthetic!$A:$M,3,0),"") -> 0.79851197 | S12: =IFERROR(VLOOKUP($C12,Synthetic!$A:$M,6,0),"") -> 302 | T12: =IFERROR(VLOOKUP($C12,Synthetic!$A:$M,4,0),"") -> 0.69081743 | U12: =IFERROR(VLOOKUP($C12,Synthetic!$A:$M,7,0),"") -> 457 | V12: =IFERROR(VLOOKUP($C12,Synthetic!$A:$M,9,0),"") -> 0.97358983 | W12: =IFERROR(VLOOKUP($C12,Synthetic!$A:$M,10,0),"") -> 0.96235983 | X12: =IF(AD12>V12,1,IF(AD12>W12,0,-1)) -> -1 | Y12: =IFERROR(VLOOKUP($C12,Synthetic!$A:$M,12,0),"") -> 0.8743238 | Z12: =U12/(U12+S12) -> 0.60210804 | AA12: =(U12*T12+S12*R12)/(U12+S12) -> 0.73366822 | AB12: =LN(AA12/(1-AA12)) -> 1.0133141 | AC12: =EXP(AB12+Y12*Z12) -> 4.6634312 | AD12: =AC12/(1+AC12) -> 0.8234286 | AE12: 1 | AF12: =IF(AE12=0,0,E12) -> 1
A13: =B13&C13 -> H0123107125 | B13: H0123 | C13: 107125 | D13: C08: Care for Older Adults – Medication Review | E13: 1 | F13: HEDIS | G13: H | H13: =VLOOKUP($C13,CutPoints!$A:$U,18,0) -> 0.98 | I13: =VLOOKUP($C13,CutPoints!$A:$U,19,0) -> 0.91 | J13: =VLOOKUP($C13,CutPoints!$A:$U,20,0) -> 0.8 | K13: =VLOOKUP($C13,CutPoints!$A:$U,21,0) -> 0.53 | L13: 839 | M13: 847 | O13: =L13/M13 -> 0.9905549 | P13: =IF(M13>=Q13, IF($G13="H",IF(ROUND(O13,2)>=H13,5,IF(ROUND(O13,2)>=I13,4,IF(ROUND(O13,2)>=J13,3,IF(ROUND(O13,2)>=K13,2,1)))),IF(ROUND(O13,2)<=H13,5,IF(ROUND(O13,2)<=I13,4,IF(ROUND(O13,2)<=J13,3,IF(ROUND(O13,2)<=K13,2,1))))), "NR") -> 5 | Q13: =IFERROR(VLOOKUP(C13,Thresholds!A:C,3,0), "") -> 30 | R13: =IFERROR(VLOOKUP($C13,Synthetic!$A:$M,3,0),"") -> 0.76111142 | S13: =IFERROR(VLOOKUP($C13,Synthetic!$A:$M,6,0),"") -> 273 | T13: =IFERROR(VLOOKUP($C13,Synthetic!$A:$M,4,0),"") -> 0.073470909 | U13: =IFERROR(VLOOKUP($C13,Synthetic!$A:$M,7,0),"") -> 491 | V13: =IFERROR(VLOOKUP($C13,Synthetic!$A:$M,9,0),"") -> 0.61751972 | W13: =IFERROR(VLOOKUP($C13,Synthetic!$A:$M,10,0),"") -> 0.60628972 | X13: =IF(AD13>V13,1,IF(AD13>W13,0,-1)) -> -1 | Y13: =IFERROR(VLOOKUP($C13,Synthetic!$A:$M,12,0),"") -> 0.012363198 | Z13: =U13/(U13+S13) -> 0.64267016 | AA13: =(U13*T13+S13*R13)/(U13+S13) -> 0.31918538 | AB13: =LN(AA13/(1-AA13)) -> -0.75751798 | AC13: =EXP(AB13+Y13*Z13) -> 0.47256852 | AD13: =AC13/(1+AC13) -> 0.32091445 | AE13: =IFERROR(X13*E13,0) -> -1 | AF13: =IF(AE13=0,0,E13) -> 1
A14: =B14&C14 -> H0123107126 | B14: H0123 | C14: 107126 | D14: C09: Care for Older Adults – Functional Status | E14: 1 | F14: HEDIS | G14: H | H14: =VLOOKUP($C14,CutPoints!$A:$U,18,0) -> 0.93 | I14: =VLOOKUP($C14,CutPoints!$A:$U,19,0) -> 0.8 | J14: =VLOOKUP($C14,CutPoints!$A:$U,20,0) -> 0.67 | K14: =VLOOKUP($C14,CutPoints!$A:$U,21,0) -> 0.48 | L14: 889 | M14: 898 | O14: =L14/M14 -> 0.98997773 | P14: =IF(M14>=Q14, IF($G14="H",IF(ROUND(O14,2)>=H14,5,IF(ROUND(O14,2)>=I14,4,IF(ROUND(O14,2)>=J14,3,IF(ROUND(O14,2)>=K14,2,1)))),IF(ROUND(O14,2)<=H14,5,IF(ROUND(O14,2)<=I14,4,IF(ROUND(O14,2)<=J14,3,IF(ROUND(O14,2)<=K14,2,1))))), "NR") -> NR | Q14: =IFERROR(VLOOKUP(C14,Thresholds!A:C,3,0), "") | R14: =IFERROR(VLOOKUP($C14,Synthetic!$A:$M,3,0),"") -> 0.80954242 | S14: =IFERROR(VLOOKUP($C14,Synthetic!$A:$M,6,0),"") -> 296 | T14: =IFERROR(VLOOKUP($C14,Synthetic!$A:$M,4,0),"") -> 0.43134903 | U14: =IFERROR(VLOOKUP($C14,Synthetic!$A:$M,7,0),"") -> 494 | V14: =IFERROR(VLOOKUP($C14,Synthetic!$A:$M,9,0),"") -> 0.5476103 | W14: =IFERROR(VLOOKUP($C14,Synthetic!$A:$M,10,0),"") -> 0.5363803 | X14: =IF(AD14>V14,1,IF(AD14>W14,0,-1)) -> 1 | Y14: =IFERROR(VLOOKUP($C14,Synthetic!$A:$M,12,0),"") -> 0.48822613 | Z14: =U14/(U14+S14) -> 0.62531646 | AA14: =(U14*T14+S14*R14)/(U14+S14) -> 0.57305187 | AB14: =LN(AA14/(1-AA14)) -> 0.29431371 | AC14: =EXP(AB14+Y14*Z14) -> 1.8214075 | AD14: =AC14/(1+AC14) -> 0.64556697 | AE14: =IFERROR(X14*E14,0) -> 1 | AF14: =IF(AE14=0,0,E14) -> 1
A15: =B15&C15 -> H0123201507 | B15: H0123 | C15: 201507 | D15: C19: Statin Therapy for Patients with Cardiovascular Disease | E15: 1 | F15: HEDIS | G15: H | H15: =VLOOKUP($C15,CutPoints!$A:$U,18,0) -> 0.91 | I15: =VLOOKUP($C15,CutPoints!$A:$U,19,0) -> 0.87 | J15: =VLOOKUP($C15,CutPoints!$A:$U,20,0) -> 0.85 | K15: =VLOOKUP($C15,CutPoints!$A:$U,21,0) -> 0.8 | L15: 659 | M15: 749 | O15: =L15/M15 -> 0.87983979 | P15: =IF(M15>=Q15, IF($G15="H",IF(ROUND(O15,2)>=H15,5,IF(ROUND(O15,2)>=I15,4,IF(ROUND(O15,2)>=J15,3,IF(ROUND(O15,2)>=K15,2,1)))),IF(ROUND(O15,2)<=H15,5,IF(ROUND(O15,2)<=I15,4,IF(ROUND(O15,2)<=J15,3,IF(ROUND(O15,2)<=K15,2,1))))), "NR") -> 4 | Q15: =IFERROR(VLOOKUP(C15,Thresholds!A:C,3,0), "") -> 30 | R15: =IFERROR(VLOOKUP($C15,Synthetic!$A:$M,3,0),"") -> 0.70067028 | S15: =IFERROR(VLOOKUP($C15,Synthetic!$A:$M,6,0),"") -> 281 | T15: =IFERROR(VLOOKUP($C15,Synthetic!$A:$M,4,0),"") -> 0.30661892 | U15: =IFERROR(VLOOKUP($C15,Synthetic!$A:$M,7,0),"") -> 405 | V15: =IFERROR(VLOOKUP($C15,Synthetic!$A:$M,9,0),"") -> 0.92711823 | W15: =IFERROR(VLOOKUP($C15,Synthetic!$A:$M,10,0),"") -> 0.91588823 | X15: =IF(AD15>V15,1,IF(AD15>W15,0,-1)) -> -1 | Y15: =IFERROR(VLOOKUP($C15,Synthetic!$A:$M,12,0),"") -> 0.090948437 | Z15: =U15/(U15+S15) -> 0.59037901 | AA15: =(U15*T15+S15*R15)/(U15+S15) -> 0.46803063 | AB15: =LN(AA15/(1-AA15)) -> -0.12805218 | AC15: =EXP(AB15+Y15*Z15) -> 0.92833916 | AD15: =AC15/(1+AC15) -> 0.48141903 | AE15: 1 | AF15: =IF(AE15=0,0,E15) -> 1
A16: =B16&C16 -> H0123600070 | B16: H0123 | C16: 600070 | D16: C17: Medication Reconciliation Post-Discharge | E16: 1 | F16: HEDIS | G16: H | H16: =VLOOKUP($C16,CutPoints!$A:$U,18,0) -> 0.85 | I16: =VLOOKUP($C16,CutPoints!$A:$U,19,0) -> 0.72 | J16: =VLOOKUP($C16,CutPoints!$A:$U,20,0) -> 0.56 | K16: =VLOOKUP($C16,CutPoints!$A:$U,21,0) -> 0.4 | L16: 570 | M16: 935 | O16: =L16/M16 -> 0.60962567 | P16: =IF(M16>=Q16, IF($G16="H",IF(ROUND(O16,2)>=H16,5,IF(ROUND(O16,2)>=I16,4,IF(ROUND(O16,2)>=J16,3,IF(ROUND(O16,2)>=K16,2,1)))),IF(ROUND(O16,2)<=H16,5,IF(ROUND(O16,2)<=I16,4,IF(ROUND(O16,2)<=J16,3,IF(ROUND(O16,2)<=K16,2,1))))), "NR") -> 3 | Q16: =IFERROR(VLOOKUP(C16,Thresholds!A:C,3,0), "") -> 30 | R16: =IFERROR(VLOOKUP($C16,Synthetic!$A:$M,3,0),"") -> 0.9340097 | S16: =IFERROR(VLOOKUP($C16,Synthetic!$A:$M,6,0),"") -> 251 | T16: =IFERROR(VLOOKUP($C16,Synthetic!$A:$M,4,0),"") -> 0.34861506 | U16: =IFERROR(VLOOKUP($C16,Synthetic!$A:$M,7,0),"") -> 445 | V16: =IFERROR(VLOOKUP($C16,Synthetic!$A:$M,9,0),"") -> 0.41154172 | W16: =IFERROR(VLOOKUP($C16,Synthetic!$A:$M,10,0),"") -> 0.40031172 | X16: =IF(AD16>V16,1,IF(AD16>W16,0,-1)) -> 1 | Y16: =IFERROR(VLOOKUP($C16,Synthetic!$A:$M,12,0),"") -> 0.032072072 | Z16: =U16/(U16+S16) -> 0.63936782 | AA16: =(U16*T16+S16*R16)/(U16+S16) -> 0.55972721 | AB16: =LN(AA16/(1-AA16)) -> 0.24005502 | AC16: =EXP(AB16+Y16*Z16) -> 1.2976577 | AD16: =AC16/(1+AC16) -> 0.56477416 | AE16: =IFERROR(X16*E16,0) -> 1 | AF16: =IF(AE16=0,0,E16) -> 1
A17: =B17&C17 -> H0123600094 | B17: H0123 | C17: 600094 | D17: C21: Follow-up after Emergency Department Visit for People with Multiple High-Risk Chronic Conditions | E17: 1 | F17: HEDIS | G17: H | H17: =VLOOKUP($C17,CutPoints!$A:$U,18,0) -> 0.72 | I17: =VLOOKUP($C17,CutPoints!$A:$U,19,0) -> 0.62 | J17: =VLOOKUP($C17,CutPoints!$A:$U,20,0) -> 0.55 | K17: =VLOOKUP($C17,CutPoints!$A:$U,21,0) -> 0.44 | L17: 435 | M17: 805 | O17: =L17/M17 -> 0.54037267 | P17: =IF(M17>=Q17, IF($G17="H",IF(ROUND(O17,2)>=H17,5,IF(ROUND(O17,2)>=I17,4,IF(ROUND(O17,2)>=J17,3,IF(ROUND(O17,2)>=K17,2,1)))),IF(ROUND(O17,2)<=H17,5,IF(ROUND(O17,2)<=I17,4,IF(ROUND(O17,2)<=J17,3,IF(ROUND(O17,2)<=K17,2,1))))), "NR") -> 2 | Q17: =IFERROR(VLOOKUP(C17,Thresholds!A:C,3,0), "") -> 30 | R17: =IFERROR(VLOOKUP($C17,Synthetic!$A:$M,3,0),"") | AE17: =IFERROR(X17*E17,0) -> 0 | AF17: =IF(AE17=0,0,E17) -> 0
A18: =B18&C18 -> H0123600452 | B18: H0123 | C18: 600452 | D18: C02: Colorectal Cancer Screening | E18: 1 | F18: HEDIS | G18: H | H18: =VLOOKUP($C18,CutPoints!$A:$U,18,0) -> 0.8 | I18: =VLOOKUP($C18,CutPoints!$A:$U,19,0) -> 0.72 | J18: =VLOOKUP($C18,CutPoints!$A:$U,20,0) -> 0.62 | K18: =VLOOKUP($C18,CutPoints!$A:$U,21,0) -> 0.5 | L18: 682 | M18: 898 | O18: =L18/M18 -> 0.75946548 | P18: =IF(M18>=Q18, IF($G18="H",IF(ROUND(O18,2)>=H18,5,IF(ROUND(O18,2)>=I18,4,IF(ROUND(O18,2)>=J18,3,IF(ROUND(O18,2)>=K18,2,1)))),IF(ROUND(O18,2)<=H18,5,IF(ROUND(O18,2)<=I18,4,IF(ROUND(O18,2)<=J18,3,IF(ROUND(O18,2)<=K18,2,1))))), "NR") -> 4 | Q18: =IFERROR(VLOOKUP(C18,Thresholds!A:C,3,0), "") -> 30 | R18: =IFERROR(VLOOKUP($C18,Synthetic!$A:$M,3,0),"") | AE18: =IFERROR(X18*E18,0) -> 0 | AF18: =IF(AE18=0,0,E18) -> 0
A19: =B19&C19 -> H0123600484 | B19: H0123 | C19: 600484 | D19: C13: Kidney Health Evaluation for Patients with Diabetes | E19: 1 | F19: HEDIS | G19: H | H19: =VLOOKUP($C19,CutPoints!$A:$U,18,0) -> 0.69 | I19: =VLOOKUP($C19,CutPoints!$A:$U,19,0) -> 0.54 | J19: =VLOOKUP($C19,CutPoints!$A:$U,20,0) -> 0.43 | K19: =VLOOKUP($C19,CutPoints!$A:$U,21,0) -> 0.23 | L19: 578 | M19: 722 | O19: =L19/M19 -> 0.80055402 | P19: =IF(M19>=Q19, IF($G19="H",IF(ROUND(O19,2)>=H19,5,IF(ROUND(O19,2)>=I19,4,IF(ROUND(O19,2)>=J19,3,IF(ROUND(O19,2)>=K19,2,1)))),IF(ROUND(O19,2)<=H19,5,IF(ROUND(O19,2)<=I19,4,IF(ROUND(O19,2)<=J19,3,IF(ROUND(O19,2)<=K19,2,1))))), "NR") -> 5 | Q19: =IFERROR(VLOOKUP(C19,Thresholds!A:C,3,0), "") -> 30 | R19: =IFERROR(VLOOKUP($C19,Synthetic!$A:$M,3,0),"") -> 0.51462073 | AE19: =IFERROR(X19*E19,0) -> 0 | AF19: =IF(AE19=0,0,E19) -> 0
A20: =B20&C20 -> H0123900793 | B20: H0123 | C20: 900793 | D20: C11: Diabetes Care – Eye Exam | E20: 1 | F20: HEDIS | G20: H | H20: =VLOOKUP($C20,CutPoints!$A:$U,18,0) -> 0.83 | I20: =VLOOKUP($C20,CutPoints!$A:$U,19,0) -> 0.77 | J20: =VLOOKUP($C20,CutPoints!$A:$U,20,0) -> 0.69 | K20: =VLOOKUP($C20,CutPoints!$A:$U,21,0) -> 0.56 | L20: 780 | M20: 981 | O20: =L20/M20 -> 0.79510703 | P20: =IF(M20>=Q20, IF($G20="H",IF(ROUND(O20,2)>=H20,5,IF(ROUND(O20,2)>=I20,4,IF(ROUND(O20,2)>=J20,3,IF(ROUND(O20,2)>=K20,2,1)))),IF(ROUND(O20,2)<=H20,5,IF(ROUND(O20,2)<=I20,4,IF(ROUND(O20,2)<=J20,3,IF(ROUND(O20,2)<=K20,2,1))))), "NR") -> 4 | Q20: =IFERROR(VLOOKUP(C20,Thresholds!A:C,3,0), "") -> 30 | R20: =IFERROR(VLOOKUP($C20,Synthetic!$A:$M,3,0),"") -> 0.067607028 | S20: =IFERROR(VLOOKUP($C20,Synthetic!$A:$M,6,0),"") -> 238 | T20: =IFERROR(VLOOKUP($C20,Synthetic!$A:$M,4,0),"") -> 0.016757958 | U20: =IFERROR(VLOOKUP($C20,Synthetic!$A:$M,7,0),"") -> 454 | V20: =IFERROR(VLOOKUP($C20,Synthetic!$A:$M,9,0),"") -> 0.46627486 | W20: =IFERROR(VLOOKUP($C20,Synthetic!$A:$M,10,0),"") -> 0.45504486 | X20: =IF(AD20>V20,1,IF(AD20>W20,0,-1)) -> -1 | Y20: =IFERROR(VLOOKUP($C20,Synthetic!$A:$M,12,0),"") -> 0.46421492 | Z20: =U20/(U20+S20) -> 0.65606936 | AA20: =(U20*T20+S20*R20)/(U20+S20) -> 0.034246511 | AB20: =LN(AA20/(1-AA20)) -> -3.3393239 | AC20: =EXP(AB20+Y20*Z20) -> 0.048085878 | AD20: =AC20/(1+AC20) -> 0.045879712 | AE20: =IFERROR(X20*E20,0) -> -1 | AF20: =IF(AE20=0,0,E20) -> 1
A21: =B21&C21 -> H0123909230 | B21: H0123 | C21: 909230 | D21: C01: Breast Cancer Screening | E21: 1 | F21: HEDIS | G21: H | H21: =VLOOKUP(909230,CutPoints!$A:$U,18,0) -> 0.82 | I21: =VLOOKUP(909230,CutPoints!$A:$U,19,0) -> 0.74 | J21: =VLOOKUP(909230,CutPoints!$A:$U,20,0) -> 0.67 | K21: =VLOOKUP(909230,CutPoints!$A:$U,21,0) -> 0.53 | L21: 523 | M21: 857 | O21: =L21/M21 -> 0.61026838 | P21: =IF(M21>=Q21, IF($G21="H",IF(ROUND(O21,2)>=H21,5,IF(ROUND(O21,2)>=I21,4,IF(ROUND(O21,2)>=J21,3,IF(ROUND(O21,2)>=K21,2,1)))),IF(ROUND(O21,2)<=H21,5,IF(ROUND(O21,2)<=I21,4,IF(ROUND(O21,2)<=J21,3,IF(ROUND(O21,2)<=K21,2,1))))), "NR") -> 2 | Q21: =IFERROR(VLOOKUP(C21,Thresholds!A:C,3,0), "") -> 30 | R21: =IFERROR(VLOOKUP($C21,Synthetic!$A:$M,3,0),"") -> 0.054463476 | S21: =IFERROR(VLOOKUP($C21,Synthetic!$A:$M,6,0),"") -> 308 | T21: =IFERROR(VLOOKUP($C21,Synthetic!$A:$M,4,0),"") -> 0.8990984 | U21: =IFERROR(VLOOKUP($C21,Synthetic!$A:$M,7,0),"") -> 464 | V21: =IFERROR(VLOOKUP($C21,Synthetic!$A:$M,9,0),"") -> 0.56178905 | W21: =IFERROR(VLOOKUP($C21,Synthetic!$A:$M,10,0),"") -> 0.55055905 | X21: =IF(AD21>V21,1,IF(AD21>W21,0,-1)) -> 1 | Y21: =IFERROR(VLOOKUP($C21,Synthetic!$A:$M,12,0),"") -> 0.66913618 | Z21: =U21/(U21+S21) -> 0.60103627 | AA21: =(U21*T21+S21*R21)/(U21+S21) -> 0.5621197 | AB21: =LN(AA21/(1-AA21)) -> 0.24976923 | AC21: =EXP(AB21+Y21*Z21) -> 1.9192689 | AD21: =AC21/(1+AC21) -> 0.65744848 | AE21: =IFERROR(X21*E21,0) -> 1 | AF21: =IF(AE21=0,0,E21) -> 1
A22: =B22&C22 -> H0123999600 | B22: H0123 | C22: 999600 | D22: C20: Transitions of Care | E22: 1 | F22: HEDIS | G22: H | H22: =VLOOKUP($C22,CutPoints!$A:$U,18,0) -> 0.78 | I22: =VLOOKUP($C22,CutPoints!$A:$U,19,0) -> 0.65 | J22: =VLOOKUP($C22,CutPoints!$A:$U,20,0) -> 0.53 | K22: =VLOOKUP($C22,CutPoints!$A:$U,21,0) -> 0.43 | L22: 600 | M22: 870 | O22: =L22/M22 -> 0.68965517 | P22: =IF(M22>=Q22, IF($G22="H",IF(ROUND(O22,2)>=H22,5,IF(ROUND(O22,2)>=I22,4,IF(ROUND(O22,2)>=J22,3,IF(ROUND(O22,2)>=K22,2,1)))),IF(ROUND(O22,2)<=H22,5,IF(ROUND(O22,2)<=I22,4,IF(ROUND(O22,2)<=J22,3,IF(ROUND(O22,2)<=K22,2,1))))), "NR") -> 4 | Q22: =IFERROR(VLOOKUP(C22,Thresholds!A:C,3,0), "") -> 30 | R22: =IFERROR(VLOOKUP($C22,Synthetic!$A:$M,3,0),"") -> 0.27430701 | S22: =IFERROR(VLOOKUP($C22,Synthetic!$A:$M,6,0),"") -> 221 | T22: =IFERROR(VLOOKUP($C22,Synthetic!$A:$M,4,0),"") -> 0.06193215 | U22: =IFERROR(VLOOKUP($C22,Synthetic!$A:$M,7,0),"") -> 417 | V22: =IFERROR(VLOOKUP($C22,Synthetic!$A:$M,9,0),"") -> 0.96538262 | W22: =IFERROR(VLOOKUP($C22,Synthetic!$A:$M,10,0),"") -> 0.95415262 | X22: =IF(AD22>V22,1,IF(AD22>W22,0,-1)) -> -1 | Y22: =IFERROR(VLOOKUP($C22,Synthetic!$A:$M,12,0),"") -> 0.83778589 | Z22: =U22/(U22+S22) -> 0.65360502 | AA22: =(U22*T22+S22*R22)/(U22+S22) -> 0.13549774 | AB22: =LN(AA22/(1-AA22)) -> -1.853199 | AC22: =EXP(AB22+Y22*Z22) -> 0.27100502 | AD22: =AC22/(1+AC22) -> 0.21322105 | AE22: =IFERROR(X22*E22,0) -> -1 | AF22: =IF(AE22=0,0,E22) -> 1
A23: =B23&C23 -> H0123999998 | B23: H0123 | C23: 999998 | D23: C12: Diabetes Care – Blood Sugar Controlled | E23: 3 | F23: HEDIS | G23: H | H23: =VLOOKUP($C23,CutPoints!$A:$U,18,0) -> 0.89 | I23: =VLOOKUP($C23,CutPoints!$A:$U,19,0) -> 0.84 | J23: =VLOOKUP($C23,CutPoints!$A:$U,20,0) -> 0.72 | K23: =VLOOKUP($C23,CutPoints!$A:$U,21,0) -> 0.49 | L23: 781 | M23: 921 | O23: =L23/M23 -> 0.84799131 | P23: =IF(M23>=Q23, IF($G23="H",IF(ROUND(O23,2)>=H23,5,IF(ROUND(O23,2)>=I23,4,IF(ROUND(O23,2)>=J23,3,IF(ROUND(O23,2)>=K23,2,1)))),IF(ROUND(O23,2)<=H23,5,IF(ROUND(O23,2)<=I23,4,IF(ROUND(O23,2)<=J23,3,IF(ROUND(O23,2)<=K23,2,1))))), "NR") -> 4 | Q23: =IFERROR(VLOOKUP(C23,Thresholds!A:C,3,0), "") -> 30 | R23: =IFERROR(VLOOKUP($C23,Synthetic!$A:$M,3,0),"") -> 0.23524027 | S23: =IFERROR(VLOOKUP($C23,Synthetic!$A:$M,6,0),"") -> 245 | T23: =IFERROR(VLOOKUP($C23,Synthetic!$A:$M,4,0),"") -> 0.88954043 | U23: =IFERROR(VLOOKUP($C23,Synthetic!$A:$M,7,0),"") -> 436 | V23: =IFERROR(VLOOKUP($C23,Synthetic!$A:$M,9,0),"") -> 0.88109711 | W23: =IFERROR(VLOOKUP($C23,Synthetic!$A:$M,10,0),"") -> 0.86986711 | X23: =IF(AD23>V23,1,IF(AD23>W23,0,-1)) -> -1 | Y23: =IFERROR(VLOOKUP($C23,Synthetic!$A:$M,12,0),"") -> 0.15298893 | Z23: =U23/(U23+S23) -> 0.64023495 | AA23: =(U23*T23+S23*R23)/(U23+S23) -> 0.6541461 | AB23: =LN(AA23/(1-AA23)) -> 0.63731427 | AC23: =EXP(AB23+Y23*Z23) -> 2.0860308 | AD23: =AC23/(1+AC23) -> 0.67595917 | AE23: =IFERROR(X23*E23,0) -> -3 | AF23: =IF(AE23=0,0,E23) -> 3
A24: =B24&C24 -> H0123999903 | B24: H0123 | C24: 999903 | D24: C04: Improving or Maintaining Physical Health | E24: 1 | F24: HOS | G24: H | H24: =VLOOKUP($C24,CutPoints!$A:$U,18,0) -> 0.75 | I24: =VLOOKUP($C24,CutPoints!$A:$U,19,0) -> 0.71 | J24: =VLOOKUP($C24,CutPoints!$A:$U,20,0) -> 0.69 | K24: =VLOOKUP($C24,CutPoints!$A:$U,21,0) -> 0.65 | O24: 0.74 | P24: =IF($G24="H",IF(ROUND(O24,2)>=H24,5,IF(ROUND(O24,2)>=I24,4,IF(ROUND(O24,2)>=J24,3,IF(ROUND(O24,2)>=K24,2,1)))),IF(ROUND(O24,2)<=H24,5,IF(ROUND(O24,2)<=I24,4,IF(ROUND(O24,2)<=J24,3,IF(ROUND(O24,2)<=K24,2,1))))) -> 4 | Q24: =IFERROR(VLOOKUP(C24,Thresholds!A:C,3,0), "")
A25: =B25&C25 -> H0123999904 | B25: H0123 | C25: 999904 | D25: C05: Improving or Maintaining Mental Health | E25: 1 | F25: HOS | G25: H | H25: =VLOOKUP($C25,CutPoints!$A:$U,18,0) -> 0.88 | I25: =VLOOKUP($C25,CutPoints!$A:$U,19,0) -> 0.85 | J25: =VLOOKUP($C25,CutPoints!$A:$U,20,0) -> 0.82 | K25: =VLOOKUP($C25,CutPoints!$A:$U,21,0) -> 0.77 | O25: 0.85 | P25: =IF($G25="H",IF(ROUND(O25,2)>=H25,5,IF(ROUND(O25,2)>=I25,4,IF(ROUND(O25,2)>=J25,3,IF(ROUND(O25,2)>=K25,2,1)))),IF(ROUND(O25,2)<=H25,5,IF(ROUND(O25,2)<=I25,4,IF(ROUND(O25,2)<=J25,3,IF(ROUND(O25,2)<=K25,2,1))))) -> 4 | Q25: =IFERROR(VLOOKUP(C25,Thresholds!A:C,3,0), "")
A26: =B26&C26 -> H0123999905 | B26: H0123 | C26: 999905 | D26: C06: Monitoring Physical Activity | E26: 1 | F26: HOS | G26: H | H26: =VLOOKUP($C26,CutPoints!$A:$U,18,0) -> 0.59 | I26: =VLOOKUP($C26,CutPoints!$A:$U,19,0) -> 0.53 | J26: =VLOOKUP($C26,CutPoints!$A:$U,20,0) -> 0.47 | K26: =VLOOKUP($C26,CutPoints!$A:$U,21,0) -> 0.41 | O26: 0.5 | P26: =IF($G26="H",IF(ROUND(O26,2)>=H26,5,IF(ROUND(O26,2)>=I26,4,IF(ROUND(O26,2)>=J26,3,IF(ROUND(O26,2)>=K26,2,1)))),IF(ROUND(O26,2)<=H26,5,IF(ROUND(O26,2)<=I26,4,IF(ROUND(O26,2)<=J26,3,IF(ROUND(O26,2)<=K26,2,1))))) -> 3 | Q26: =IFERROR(VLOOKUP(C26,Thresholds!A:C,3,0), "")
A27: =B27&C27 -> H0123999909 | B27: H0123 | C27: 999909 | D27: C16: Improving Bladder Control | E27: 1 | F27: HOS | G27: H | H27: =VLOOKUP($C27,CutPoints!$A:$U,18,0) -> 0.52 | I27: =VLOOKUP($C27,CutPoints!$A:$U,19,0) -> 0.48 | J27: =VLOOKUP($C27,CutPoints!$A:$U,20,0) -> 0.44 | K27: =VLOOKUP($C27,CutPoints!$A:$U,21,0) -> 0.39 | O27: 0.46 | P27: =IF($G27="H",IF(ROUND(O27,2)>=H27,5,IF(ROUND(O27,2)>=I27,4,IF(ROUND(O27,2)>=J27,3,IF(ROUND(O27,2)>=K27,2,1)))),IF(ROUND(O27,2)<=H27,5,IF(ROUND(O27,2)<=I27,4,IF(ROUND(O27,2)<=J27,3,IF(ROUND(O27,2)<=K27,2,1))))) -> 3 | Q27: =IFERROR(VLOOKUP(C27,Thresholds!A:C,3,0), "")
A28: =B28&C28 -> H0123999910 | B28: H0123 | C28: 999910 | D28: C15: Reducing the Risk of Falling | E28: 1 | F28: HOS | G28: H | H28: =VLOOKUP($C28,CutPoints!$A:$U,18,0) -> 0.71 | I28: =VLOOKUP($C28,CutPoints!$A:$U,19,0) -> 0.62 | J28: =VLOOKUP($C28,CutPoints!$A:$U,20,0) -> 0.55 | K28: =VLOOKUP($C28,CutPoints!$A:$U,21,0) -> 0.49 | O28: 0.71 | P28: =IF($G28="H",IF(ROUND(O28,2)>=H28,5,IF(ROUND(O28,2)>=I28,4,IF(ROUND(O28,2)>=J28,3,IF(ROUND(O28,2)>=K28,2,1)))),IF(ROUND(O28,2)<=H28,5,IF(ROUND(O28,2)<=I28,4,IF(ROUND(O28,2)<=J28,3,IF(ROUND(O28,2)<=K28,2,1))))) -> 5 | Q28: =IFERROR(VLOOKUP(C28,Thresholds!A:C,3,0), "")
A29: =B29&C29 -> H0123999802 | B29: H0123 | C29: 999802 | D29: D01: Call Center – Foreign Language Interpreter and TTY Availability | E29: 2 | F29: Ops | G29: H | H29: =VLOOKUP($C29,CutPoints!$A:$U,18,0) -> 0.99 | I29: =VLOOKUP($C29,CutPoints!$A:$U,19,0) -> 0.9 | J29: =VLOOKUP($C29,CutPoints!$A:$U,20,0) -> 0.74 | K29: =VLOOKUP($C29,CutPoints!$A:$U,21,0) -> 0.4 | O29: 0.9 | P29: =IF($G29="H",IF(ROUND(O29,2)>=H29,5,IF(ROUND(O29,2)>=I29,4,IF(ROUND(O29,2)>=J29,3,IF(ROUND(O29,2)>=K29,2,1)))),IF(ROUND(O29,2)<=H29,5,IF(ROUND(O29,2)<=I29,4,IF(ROUND(O29,2)<=J29,3,IF(ROUND(O29,2)<=K29,2,1))))) -> 4 | Q29: =IFERROR(VLOOKUP(C29,Thresholds!A:C,3,0), "")
A30: =B30&C30 -> H0123999806 | B30: H0123 | C30: 999806 | D30: D02: Complaints about the Drug Plan | E30: 2 | F30: Ops | G30: L | H30: =VLOOKUP($C30,CutPoints!$A:$U,18,0) -> 0.12 | I30: =VLOOKUP($C30,CutPoints!$A:$U,19,0) -> 0.38 | J30: =VLOOKUP($C30,CutPoints!$A:$U,20,0) -> 0.77 | K30: =VLOOKUP($C30,CutPoints!$A:$U,21,0) -> 1.4 | L30: 20 | M30: 4523 | O30: =L30/M30*30000/365 -> 0.36343923 | P30: =IF(M30>=Q30, IF($G30="H",IF(ROUND(O30,2)>=H30,5,IF(ROUND(O30,2)>=I30,4,IF(ROUND(O30,2)>=J30,3,IF(ROUND(O30,2)>=K30,2,1)))),IF(ROUND(O30,2)<=H30,5,IF(ROUND(O30,2)<=I30,4,IF(ROUND(O30,2)<=J30,3,IF(ROUND(O30,2)<=K30,2,1))))), "NR") -> 4 | Q30: =IFERROR(VLOOKUP(C30,Thresholds!A:C,3,0), "") -> 800
A31: =B31&C31 -> H0123999808 | B31: H0123 | C31: 999808 | D31: D03: Members Choosing to Leave the Plan | E31: 2 | F31: Ops | G31: L | H31: =VLOOKUP($C31,CutPoints!$A:$U,18,0) -> 0.09 | I31: =VLOOKUP($C31,CutPoints!$A:$U,19,0) -> 0.17 | J31: =VLOOKUP($C31,CutPoints!$A:$U,20,0) -> 0.27 | K31: =VLOOKUP($C31,CutPoints!$A:$U,21,0) -> 0.39 | L31: 879 | M31: 4523 | O31: =L31/M31 -> 0.19434004 | P31: =IF(M31>=Q31, IF($G31="H",IF(ROUND(O31,2)>=H31,5,IF(ROUND(O31,2)>=I31,4,IF(ROUND(O31,2)>=J31,3,IF(ROUND(O31,2)>=K31,2,1)))),IF(ROUND(O31,2)<=H31,5,IF(ROUND(O31,2)<=I31,4,IF(ROUND(O31,2)<=J31,3,IF(ROUND(O31,2)<=K31,2,1))))), "NR") -> 3 | Q31: =IFERROR(VLOOKUP(C31,Thresholds!A:C,3,0), "") -> 1000
A32: =B32&C32 -> H0123999814 | B32: H0123 | C32: 999814 | D32: D07: MPF Price Accuracy | E32: 1 | F32: Ops | G32: H | H32: =VLOOKUP($C32,CutPoints!$A:$U,18,0) -> 0.99 | I32: =VLOOKUP($C32,CutPoints!$A:$U,19,0) -> 0.97 | J32: =VLOOKUP($C32,CutPoints!$A:$U,20,0) -> 0.96 | K32: =VLOOKUP($C32,CutPoints!$A:$U,21,0) -> 0.94 | O32: 0.989 | P32: =IF($G32="H",IF(ROUND(O32,2)>=H32,5,IF(ROUND(O32,2)>=I32,4,IF(ROUND(O32,2)>=J32,3,IF(ROUND(O32,2)>=K32,2,1)))),IF(ROUND(O32,2)<=H32,5,IF(ROUND(O32,2)<=I32,4,IF(ROUND(O32,2)<=J32,3,IF(ROUND(O32,2)<=K32,2,1))))) -> 5 | Q32: =IFERROR(VLOOKUP(C32,Thresholds!A:C,3,0), "")
A33: =B33&C33 -> H0123999916 | B33: H0123 | C33: 999916 | D33: C28: Complaints about the Health Plan | E33: 2 | F33: Ops | G33: L | H33: =VLOOKUP($C33,CutPoints!$A:$U,18,0) -> 0.12 | I33: =VLOOKUP($C33,CutPoints!$A:$U,19,0) -> 0.38 | J33: =VLOOKUP($C33,CutPoints!$A:$U,20,0) -> 0.77 | K33: =VLOOKUP($C33,CutPoints!$A:$U,21,0) -> 1.4 | L33: 20 | M33: 4523 | O33: =L33/M33*30000/365 -> 0.36343923 | P33: =IF(M33>=Q33, IF($G33="H",IF(ROUND(O33,2)>=H33,5,IF(ROUND(O33,2)>=I33,4,IF(ROUND(O33,2)>=J33,3,IF(ROUND(O33,2)>=K33,2,1)))),IF(ROUND(O33,2)<=H33,5,IF(ROUND(O33,2)<=I33,4,IF(ROUND(O33,2)<=J33,3,IF(ROUND(O33,2)<=K33,2,1))))), "NR") -> 4 | Q33: =IFERROR(VLOOKUP(C33,Thresholds!A:C,3,0), "") -> 800
A34: =B34&C34 -> H0123999918 | B34: H0123 | C34: 999918 | D34: C29: Members Choosing to Leave the Plan | E34: 2 | F34: Ops | G34: L | H34: =VLOOKUP($C34,CutPoints!$A:$U,18,0) -> 0.09 | I34: =VLOOKUP($C34,CutPoints!$A:$U,19,0) -> 0.17 | J34: =VLOOKUP($C34,CutPoints!$A:$U,20,0) -> 0.27 | K34: =VLOOKUP($C34,CutPoints!$A:$U,21,0) -> 0.39 | L34: 879 | M34: 4523 | O34: =L34/M34 -> 0.19434004 | P34: =IF(M34>=Q34, IF($G34="H",IF(ROUND(O34,2)>=H34,5,IF(ROUND(O34,2)>=I34,4,IF(ROUND(O34,2)>=J34,3,IF(ROUND(O34,2)>=K34,2,1)))),IF(ROUND(O34,2)<=H34,5,IF(ROUND(O34,2)<=I34,4,IF(ROUND(O34,2)<=J34,3,IF(ROUND(O34,2)<=K34,2,1))))), "NR") -> 3 | Q34: =IFERROR(VLOOKUP(C34,Thresholds!A:C,3,0), "") -> 1000
A35: =B35&C35 -> H0123999919 | B35: H0123 | C35: 999919 | D35: C31: Plan Makes Timely Decisions about Appeals | E35: 2 | F35: Ops | G35: H | H35: =VLOOKUP($C35,CutPoints!$A:$U,18,0) -> 0.99 | I35: =VLOOKUP($C35,CutPoints!$A:$U,19,0) -> 0.95 | J35: =VLOOKUP($C35,CutPoints!$A:$U,20,0) -> 0.85 | K35: =VLOOKUP($C35,CutPoints!$A:$U,21,0) -> 0.69 | L35: 13 | M35: 15 | O35: =L35/M35 -> 0.86666667 | P35: =IF(M35>=Q35, IF($G35="H",IF(ROUND(O35,2)>=H35,5,IF(ROUND(O35,2)>=I35,4,IF(ROUND(O35,2)>=J35,3,IF(ROUND(O35,2)>=K35,2,1)))),IF(ROUND(O35,2)<=H35,5,IF(ROUND(O35,2)<=I35,4,IF(ROUND(O35,2)<=J35,3,IF(ROUND(O35,2)<=K35,2,1))))), "NR") -> 3 | Q35: =IFERROR(VLOOKUP(C35,Thresholds!A:C,3,0), "") -> 11
A36: =B36&C36 -> H0123999920 | B36: H0123 | C36: 999920 | D36: C32: Reviewing Appeals Decisions | E36: 2 | F36: Ops | G36: H | H36: =VLOOKUP($C36,CutPoints!$A:$U,18,0) -> 1 | I36: =VLOOKUP($C36,CutPoints!$A:$U,19,0) -> 0.97 | J36: =VLOOKUP($C36,CutPoints!$A:$U,20,0) -> 0.92 | K36: =VLOOKUP($C36,CutPoints!$A:$U,21,0) -> 0.78 | L36: 14 | M36: 15 | O36: =L36/M36 -> 0.93333333 | P36: =IF(M36>=Q36, IF($G36="H",IF(ROUND(O36,2)>=H36,5,IF(ROUND(O36,2)>=I36,4,IF(ROUND(O36,2)>=J36,3,IF(ROUND(O36,2)>=K36,2,1)))),IF(ROUND(O36,2)<=H36,5,IF(ROUND(O36,2)<=I36,4,IF(ROUND(O36,2)<=J36,3,IF(ROUND(O36,2)<=K36,2,1))))), "NR") -> 3 | Q36: =IFERROR(VLOOKUP(C36,Thresholds!A:C,3,0), "") -> 11
A37: =B37&C37 -> H0123999921 | B37: H0123 | C37: 999921 | D37: C33: Call Center – Foreign Language Interpreter and TTY Availability | E37: 2 | F37: Ops | G37: H | H37: =VLOOKUP($C37,CutPoints!$A:$U,18,0) -> 0.99 | I37: =VLOOKUP($C37,CutPoints!$A:$U,19,0) -> 0.93 | J37: =VLOOKUP($C37,CutPoints!$A:$U,20,0) -> 0.69 | K37: =VLOOKUP($C37,CutPoints!$A:$U,21,0) -> 0.46 | O37: 0.99 | P37: =IF($G37="H",IF(ROUND(O37,2)>=H37,5,IF(ROUND(O37,2)>=I37,4,IF(ROUND(O37,2)>=J37,3,IF(ROUND(O37,2)>=K37,2,1)))),IF(ROUND(O37,2)<=H37,5,IF(ROUND(O37,2)<=I37,4,IF(ROUND(O37,2)<=J37,3,IF(ROUND(O37,2)<=K37,2,1))))) -> 5 | Q37: =IFERROR(VLOOKUP(C37,Thresholds!A:C,3,0), "")
A38: =B38&C38 -> H0123999925 | B38: H0123 | C38: 999925 | D38: C07: Special Needs Plan (SNP) Care Management | E38: 1 | F38: Ops | G38: H | H38: =VLOOKUP($C38,CutPoints!$A:$U,18,0) -> 0.87 | I38: =VLOOKUP($C38,CutPoints!$A:$U,19,0) -> 0.74 | J38: =VLOOKUP($C38,CutPoints!$A:$U,20,0) -> 0.6 | K38: =VLOOKUP($C38,CutPoints!$A:$U,21,0) -> 0.43 | L38: 686 | M38: 868 | O38: =L38/M38 -> 0.79032258 | P38: =IF(M38>=Q38, IF($G38="H",IF(ROUND(O38,2)>=H38,5,IF(ROUND(O38,2)>=I38,4,IF(ROUND(O38,2)>=J38,3,IF(ROUND(O38,2)>=K38,2,1)))),IF(ROUND(O38,2)<=H38,5,IF(ROUND(O38,2)<=I38,4,IF(ROUND(O38,2)<=J38,3,IF(ROUND(O38,2)<=K38,2,1))))), "NR") -> 4 | Q38: =IFERROR(VLOOKUP(C38,Thresholds!A:C,3,0), "") -> 30
A39: =B39&C39 -> H0123201180 | B39: H0123 | C39: 201180 | D39: D10: Medication Adherence for Cholesterol (Statins) | E39: 3 | F39: PatientSafety | G39: H | H39: =VLOOKUP($C39,CutPoints!$A:$U,18,0) -> 0.92 | I39: =VLOOKUP($C39,CutPoints!$A:$U,19,0) -> 0.89 | J39: =VLOOKUP($C39,CutPoints!$A:$U,20,0) -> 0.86 | K39: =VLOOKUP($C39,CutPoints!$A:$U,21,0) -> 0.82 | L39: 757 | M39: 851 | O39: =L39/M39 -> 0.88954172 | P39: =IF(M39>=Q39, IF($G39="H",IF(ROUND(O39,2)>=H39,5,IF(ROUND(O39,2)>=I39,4,IF(ROUND(O39,2)>=J39,3,IF(ROUND(O39,2)>=K39,2,1)))),IF(ROUND(O39,2)<=H39,5,IF(ROUND(O39,2)<=I39,4,IF(ROUND(O39,2)<=J39,3,IF(ROUND(O39,2)<=K39,2,1))))), "NR") -> 4 | Q39: =IFERROR(VLOOKUP(C39,Thresholds!A:C,3,0), "") -> 30 | R39: =IFERROR(VLOOKUP($C39,Synthetic!$A:$M,3,0),"") -> 0.39347265 | S39: =IFERROR(VLOOKUP($C39,Synthetic!$A:$M,6,0),"") -> 279 | T39: =IFERROR(VLOOKUP($C39,Synthetic!$A:$M,4,0),"") -> 0.51893375 | U39: =IFERROR(VLOOKUP($C39,Synthetic!$A:$M,7,0),"") -> 485 | V39: =IFERROR(VLOOKUP($C39,Synthetic!$A:$M,9,0),"") -> 0.42460278 | W39: =IFERROR(VLOOKUP($C39,Synthetic!$A:$M,10,0),"") -> 0.41337278 | X39: =IF(AD39>V39,1,IF(AD39>W39,0,-1)) -> 1 | Y39: =IFERROR(VLOOKUP($C39,Synthetic!$A:$M,12,0),"") -> 0.83755063 | Z39: =U39/(U39+S39) -> 0.63481675 | AA39: =(U39*T39+S39*R39)/(U39+S39) -> 0.47311746 | AB39: =LN(AA39/(1-AA39)) -> -0.10763397 | AC39: =EXP(AB39+Y39*Z39) -> 1.528149 | AD39: =AC39/(1+AC39) -> 0.60445369 | AE39: =IFERROR(X39*E39,0) -> 3 | AF39: =IF(AE39=0,0,E39) -> 3
A40: =B40&C40 -> H0123201181 | B40: H0123 | C40: 201181 | D40: D09: Medication Adherence for Hypertension (RAS antagonists) | E40: 3 | F40: PatientSafety | G40: H | H40: =VLOOKUP($C40,CutPoints!$A:$U,18,0) -> 0.92 | I40: =VLOOKUP($C40,CutPoints!$A:$U,19,0) -> 0.9 | J40: =VLOOKUP($C40,CutPoints!$A:$U,20,0) -> 0.87 | K40: =VLOOKUP($C40,CutPoints!$A:$U,21,0) -> 0.83 | L40: 798 | M40: 897 | O40: =L40/M40 -> 0.88963211 | P40: =IF(M40>=Q40, IF($G40="H",IF(ROUND(O40,2)>=H40,5,IF(ROUND(O40,2)>=I40,4,IF(ROUND(O40,2)>=J40,3,IF(ROUND(O40,2)>=K40,2,1)))),IF(ROUND(O40,2)<=H40,5,IF(ROUND(O40,2)<=I40,4,IF(ROUND(O40,2)<=J40,3,IF(ROUND(O40,2)<=K40,2,1))))), "NR") -> 3 | Q40: =IFERROR(VLOOKUP(C40,Thresholds!A:C,3,0), "") -> 30 | R40: =IFERROR(VLOOKUP($C40,Synthetic!$A:$M,3,0),"") -> 0.91053914 | S40: =IFERROR(VLOOKUP($C40,Synthetic!$A:$M,6,0),"") -> 251 | T40: =IFERROR(VLOOKUP($C40,Synthetic!$A:$M,4,0),"") -> 0.64139761 | U40: =IFERROR(VLOOKUP($C40,Synthetic!$A:$M,7,0),"") -> 401 | V40: =IFERROR(VLOOKUP($C40,Synthetic!$A:$M,9,0),"") -> 0.46717876 | W40: =IFERROR(VLOOKUP($C40,Synthetic!$A:$M,10,0),"") -> 0.45594876 | X40: =IF(AD40>V40,1,IF(AD40>W40,0,-1)) -> 1 | Y40: =IFERROR(VLOOKUP($C40,Synthetic!$A:$M,12,0),"") -> 0.069243975 | Z40: =U40/(U40+S40) -> 0.61503067 | AA40: =(U40*T40+S40*R40)/(U40+S40) -> 0.74500884 | AB40: =LN(AA40/(1-AA40)) -> 1.0721672 | AC40: =EXP(AB40+Y40*Z40) -> 3.0488192 | AD40: =AC40/(1+AC40) -> 0.75301441 | AE40: =IFERROR(X40*E40,0) -> 3 | AF40: =IF(AE40=0,0,E40) -> 3
...

Sheet Synthetic
A1: Measure ID | B1: Measure Name | C1: SRF Rate Prev Yr | D1: SRF Rate Curr Yr | E1: Δ Rate | F1: Denom Prev | G1: Denom Curr | H1: Δ Denom | I1: HEI Upper | J1: HEI Lower | K1: Avg Rate vs HEI | L1: LOG Odds | M1: Interpretation
A2: 999810 | B2: D05 Rating of Drug Plan | C2: 0.842 | D2: 0.848 | F2: 400 | G2: 430 | I2: 0.89765 | J2: 0.87657 | K2: Below Lower Band | L2: 0.9323 | M2: Slight gain; still below HEI threshold
A3: 999811 | B3: D06 Getting Needed Rx Drugs | C3: 0.11228143 | D3: 0.51974656 | F3: 251 | G3: 437 | I3: 0.022320152 | J3: 0.011090152 | K3: Below Lower Band | L3: 0.70906829 | M3: Decline; experience measure risk
A4: 999901 | B4: C03 Annual Flu Vaccine | C4: 0.015265875 | D4: 0.23074255 | F4: 342 | G4: 484 | I4: 0.65279442 | J4: 0.64156442 | K4: Below Lower Band | L4: 0.73038471 | M4: Modest improvement
A5: 999911 | B5: C22–C27 CAHPS Composite Group | C5: 0.95874412 | D5: 0.61110454 | F5: 224 | G5: 430 | I5: 0.27857366 | J5: 0.26734366 | K5: Below Lower Band | L5: 0.38813083 | M5: Flat; need CAHPS improvement
A6: 999915 | B6: C22–C27 CAHPS Composite Group | C6: 0.4982027 | D6: 0.62447198 | F6: 259 | G6: 494 | I6: 0.53052463 | J6: 0.51929463 | K6: Below Lower Band | L6: 0.66290993 | M6: Flat; need CAHPS improvement
A7: 999922 | B7: C22–C27 CAHPS Composite Group | C7: 0.89561684 | D7: 0.16113844 | F7: 259 | G7: 439 | I7: 0.7609 | J7: 0.72342 | K7: Below Lower Band | L7: 0.78525777 | M7: Flat; need CAHPS improvement
A8: 101803 | B8: C14 Controlling High BP | C8: 0.26478043 | D8: 0.7029064 | F8: 305 | G8: 402 | I8: 0.52002983 | J8: 0.50879983 | K8: Below Lower Band | L8: 0.62742444 | M8: Large denom increase; verify stability
A9: 104201 | B9: C10 Osteoporosis Mgmt | C9: 0.79851197 | D9: 0.69081743 | F9: 302 | G9: 457 | I9: 0.97358983 | J9: 0.96235983 | K9: Below Lower Band | L9: 0.8743238 | M9: Consistent
A10: 107125 | B10: C08–C09 Care for Older Adults | C10: 0.76111142 | D10: 0.073470909 | F10: 273 | G10: 491 | I10: 0.61751972 | J10: 0.60628972 | K10: Below Lower Band | L10: 0.012363198 | M10: Stable
A11: 107126 | C11: 0.80954242 | D11: 0.43134903 | F11: 296 | G11: 494 | I11: 0.5476103 | J11: 0.5363803 | K11: Below Lower Band | L11: 0.48822613
A12: 201507 | B12: C19 Statin Therapy for CVD | C12: 0.70067028 | D12: 0.30661892 | F12: 281 | G12: 405 | I12: 0.92711823 | J12: 0.91588823 | K12: Below Lower Band | L12: 0.090948437 | M12: Opportunity to lift above HEI
A13: 600070 | B13: C17–C13 Clinical Follow-up Group | C13: 0.9340097 | D13: 0.34861506 | F13: 251 | G13: 445 | I13: 0.41154172 | J13: 0.40031172 | K13: Below Lower Band | L13: 0.032072072 | M13: Stable
A14: 600484 | C14: 0.51462073 | D14: 0.15607962 | F14: 269 | G14: 434 | I14: 0.24657905 | J14: 0.23534905 | L14: 0.45176652
A15: 900793 | B15: C11 Diabetes Eye Exam | C15: 0.067607028 | D15: 0.016757958 | F15: 238 | G15: 454 | I15: 0.46627486 | J15: 0.45504486 | K15: Below Lower Band | L15: 0.46421492 | M15: Stable
A16: 909230 | B16: C01 Breast Cancer Screening | C16: 0.054463476 | D16: 0.8990984 | F16: 308 | G16: 464 | I16: 0.56178905 | J16: 0.55055905 | K16: Below Lower Band | L16: 0.66913618 | M16: Stable
A17: 999600 | B17: C20 Transitions of Care | C17: 0.27430701 | D17: 0.06193215 | F17: 221 | G17: 417 | I17: 0.96538262 | J17: 0.95415262 | K17: Below Lower Band | L17: 0.83778589 | M17: Stable
A18: 999998 | B18: C12 Diabetes – Blood Sugar Controlled | C18: 0.23524027 | D18: 0.88954043 | F18: 245 | G18: 436 | I18: 0.88109711 | J18: 0.86986711 | K18: Below Lower Band | L18: 0.15298893 | M18: Stable
A19: 201180 | B19: D08–D12 Medication Adherence Group | C19: 0.39347265 | D19: 0.51893375 | F19: 279 | G19: 485 | I19: 0.42460278 | J19: 0.41337278 | K19: Below Lower Band | L19: 0.83755063 | M19: Stable; key 4★ opportunity
A20: 201181 | B20: D08–D12 Medication Adherence Group | C20: 0.91053914 | D20: 0.64139761 | F20: 251 | G20: 401 | I20: 0.46717876 | J20: 0.45594876 | K20: Below Lower Band | L20: 0.069243975 | M20: Stable; key 4★ opportunity
A21: 201182 | B21: D08–D12 Medication Adherence Group | C21: 0.29618441 | D21: 0.0071396958 | F21: 319 | G21: 474 | I21: 0.62623837 | J21: 0.61500837 | K21: Below Lower Band | L21: 0.90545751 | M21: Stable; key 4★ opportunity
A22: 201183 | B22: D08–D12 Medication Adherence Group | C22: 0.93553956 | D22: 0.11184257 | F22: 233 | G22: 478 | I22: 0.59418397 | J22: 0.58295397 | K22: Below Lower Band | L22: 0.64069233 | M22: Stable; key 4★ opportunity
A23: 201185 | B23: Safety & Polypharmacy Group | C23: 0.69181197 | D23: 0.59046835 | F23: 201 | G23: 446 | I23: 0.090151271 | J23: 0.078921271 | K23: Below Lower Band | L23: 0.88299336 | M23: Stable
A24: 201187 | B24: Safety & Polypharmacy Group | C24: 0.16476524 | D24: 0.6366306 | F24: 342 | G24: 418 | I24: 0.7773855 | J24: 0.7661555 | K24: Below Lower Band | L24: 0.402595 | M24: Stable
A25: 108009 | B25: C18 Plan All-Cause Readmissions | C25: 0.143534 | D25: 0.133535 | F25: 213 | G25: 404 | I25: 0.18062515 | J25: 0.16939515 | K25: Below Lower Band | L25: 0.68249428 | M25: Slight gain; still below HEI

Sheet Sheet1
L1: EYE Exam
B2: Domain | C2: Measue Weight | D2: Previous PIT | E2: Previous YE | F2: Current PIT | G2: Forecasted YE for 4 STARS | K2: 5 CUT POINT | L2: 4 CUT POINT | M2: 3 CUT POINT | N2: 2CUT POINT
B3: HEDIS | C3: 16 | D3: 3.42 | E3: 3.55 | F3: 3.33 | G3: 3.87 | J3: HARD | K3: 0.89 | L3: 0.87 | M3: 0.85 | N3: 0.81
B4: PatientSafety | C4: 12 | D4: 4.21 | E4: 4.44 | F4: 4.4 | G4: 4.56 | J4: MID | K4: 0.87 | L4: 0.85 | M4: 0.83 | N4: 0.79
B5: Ops | C5: 18 | D5: 3.57 | E5: 3.78 | F5: 3.67 | G5: 4.5 | J5: EASY | K5: 0.85 | L5: 0.83 | M5: 0.81 | N5: 0.78
B6: CAHPS | C6: 17 | D6: 4 | E6: 4.13 | F6: 4.01 | G6: 4.34
B7: HOS | C7: 9 | D7: 2.97 | E7: 3.01 | F7: 2.54 | G7: 3.33
B8: QI | C8: 10 | D8: 3 | E8: 3.75 | F8: 3.5 | G8: 4
B9: Readmits | C9: 3 | D9: 4.2 | E9: 4.5 | F9: 4.1 | G9: 4.8
B12: HEDIS | C12: Weight | D12: Previous PIT | E12: Previous YE | F12: Current PIT | G12: Forecasted YE | H12: Number of Individuals
B13: Diab- Eye Exam | C13: 3 | D13: 0.78 | E13: 0.81 | F13: 0.75 | G13: 0.845 | H13: 250
B14: Diab - HB1AC | C14: 1 | D14: 0.56 | E14: 0.71 | F14: 0.58 | G14: 0.782 | H14: 11
B15: BCS | C15: 3 | D15: 0.66 | E15: 0.81 | F15: 0.623 | G15: 0.867 | H15: 45
B16: COL | C16: 2 | D16: 0.67 | E16: 0.79 | F16: 0.69 | G16: 0.87 | H16: 76
B17: FMC | C17: 1 | D17: 0.562 | E17: 0.68 | F17: 0.58 | G17: 0.78 | H17: 123
B18: TOC | C18: 1 | D18: 0.61 | E18: 0.674 | F18: 0.52 | G18: 0.76 | H18: 67
B20: MA
B22: CAHPS
B24: HOS
B26: QI
B28: READMITS

Sheet Stars Calculator
E1: 1625000 | I1: Actual Perf | J1: Simulation 1 | L1: QBP
F2: Stars Calculator: North Star Health Plan | I2: H0123 | L2: PMPM | M2: Yearly | N2: Impact | O2: Change if any | P2: Delta
I3: PPO | L3: 1000 | M3: =J4*L3*12 -> 0 | N3: =IF(J5<=3.5,0,5/100) -> 0 | O3: =M3+(M3*N3) -> 0 | P3: =O3-M3 -> 0
H4: Enrollment | I4: 50000 | L4: Rebate
H5: Overall Star | I5: =IFERROR(IF(ROUND(I$6,6)>=4.75, 5, IF(ROUND(I$6,6)>=4.25, 4.5, IF(ROUND(I$6,6)>=3.75, 4, IF(ROUND(I$6,6)>=3.25, 3.5, IF(ROUND(I$6,6)>=2.75, 3, IF(ROUND(I$6,6)>=2.25, 2.5,IF(ROUND(I$6,6)>=1.75, 2, 1.5))))))), "NR") -> 3.5 | L5: Bid PMPM | N5: =L3 -> 1000 | O5: Total Impact
H6: Overall Rate with CAI and HEI Reward | I6: =I$7+I$8 -> 3.6989703 | L6: Benchmark PMPM | N6: =IF(J5=3.5,1050,1100) -> 1100 | O6: =IF(J5>=4,P3+N12,0) -> 0
H7: HEI Reward | I7: ='HEI Calculation'!$I$2 -> 0.16 | L7: Benchmark Annual | N7: =J4*N6 -> 0
H8: Overall Rate with CAI | I8: =IF(AND(I$11>3.75,I$11>I$10),I$11,I$10) + I$9 -> 3.5389703 | L8: Benchmark Difference PMPM | N8: =N6-N5 -> 100
H9: CAI | I9: 0.003256 | L9: Rebate % | N9: =IF(J5<>4,65/100,70/100) -> 0.65
H10: Overall Mean Score wQI | I10: {=IFERROR(SUMPRODUCT((I$21:I$65<>"NR")*($G$21:$G$65), (I$21:I$65))/SUMIFS($G$21:$G$65, I$21:I$65, "<>NR"), "NR")} -> 3.5357143 | L10: Rebate PMPM | N10: =N9*N8 -> 65
H11: Overall Mean Score woQI | I11: {=IFERROR(SUMPRODUCT(($A$21:$A$65="N")*(I$21:I$65<>"NR")*($G$21:$G$65), (I$21:I$65))/SUMIFS($G$21:$G$65, $A$21:$A$65, "N", I$21:I$65, "<>NR"), "NR")} -> 3.6081081 | L11: Rebate Annual | N11: =IF(J4<>4,N10*I4,N10*J4) -> 3250000
H12: Part C Rating | I12: {=IFERROR(SUMPRODUCT(($B$21:$B$65="C")*(I$21:I$65<>"NR")*($G$21:$G$65), (I$21:I$65))/SUMIFS($G$21:$G$65, $B$21:$B$65, "C", I$21:I$65, "<>NR"), "NR")} -> 3.7857143 | L12: Delta | N12: =N11-E1 -> 1625000
H13: Part D Rating | I13: {=IFERROR(SUMPRODUCT(($B$21:$B$65="D")*(I$21:I$65<>"NR")*($G$21:$G$65), (I$21:I$65))/SUMIFS($G$21:$G$65, $B$21:$B$65, "D", I$21:I$65, "<>NR"), "NR")} -> 3.0357143
H14: HEDIS | I14: {=IFERROR(SUMPRODUCT(($H$30:$H$41=$H14)*($C$30:$C$41="N")*(I$30:I$41<>"NR")*($G$30:$G$41), (I$30:I$41))/SUMIFS($G$30:$G$41, $H$30:$H$41, $H14, I$30:I$41, "<>NR"), "NR")} -> 3.7333333
H15: PatientSafety | I15: {=IFERROR(SUMPRODUCT(($H$57:$H$62=$H15)*($C$57:$C$62="N")*(I$57:I$62<>"NR")*($G$57:$G$62), (I$57:I$62))/SUMIFS($G$57:$G$62, $H$57:$H$62, $H15, I$57:I$62, "<>NR"), "NR")} -> 3
H16: Ops | I16: {=IFERROR(SUMPRODUCT(($H$47:$H$56=$H16)*($C$47:$C$56="N")*(I$47:I$56<>"NR")*($G$47:$G$56), (I$47:I$56))/SUMIFS($G$47:$G$56, $H$47:$H$56, $H16, I$47:I$56, "<>NR", $C$47:$C$56, "N"), "NR")} -> 3.6428571
H17: CAHPS | I17: {=IFERROR(SUMPRODUCT(($H$21:$H$29=$H17)*($C$21:$C$29="N")*(I$21:I$29<>"NR")*($G$21:$G$29), (I$21:I$29))/SUMIFS($G$21:$G$29, $H$21:$H$29, $H17, I$21:I$29, "<>NR"), "NR")} -> 3.5294118
H18: HOS | I18: {=IFERROR(SUMPRODUCT(($H$42:$H$46=$H18)*($C$42:$C$46="N")*(I$42:I$46<>"NR")*($G$42:$G$46), (I$42:I$46))/SUMIFS($G$42:$G$46, $H$42:$H$46, $H18, I$42:I$46, "<>NR"), "NR")} -> 3.8888889
H19: QI | I19: =AVERAGE(I$63:I$64) -> 3
A20: QI Ind | B20: PartC/D | C20: Dup Ind | D20: Trend Ind | E20: MeasureID | F20: MeasureName | G20: Weight | H20: Domain | I20: Measure Star | O20: 0.05
A21: N | B21: C | C21: N | D21: H | E21: 999901 | F21: Annual Flu Vaccine | G21: 1 | H21: CAHPS | I21: =VLOOKUP(I$2&$E21, 'Data for Analysis'!$A:$P,16,0) -> 2
A22: N | B22: C | C22: N | D22: H | E22: 999922 | F22: Care Coordination | G22: 2 | H22: CAHPS | I22: =VLOOKUP(I$2&$E22, 'Data for Analysis'!$A:$P,16,0) -> 4
A23: N | B23: C | C23: N | D23: H | E23: 999913 | F23: Customer Service | G23: 2 | H23: CAHPS | I23: =VLOOKUP(I$2&$E23, 'Data for Analysis'!$A:$P,16,0) -> 3
A24: N | B24: C | C24: N | D24: H | E24: 999912 | F24: Getting Appointments and Care Quickly | G24: 2 | H24: CAHPS | I24: =VLOOKUP(I$2&$E24, 'Data for Analysis'!$A:$P,16,0) -> 5
A25: N | B25: C | C25: N | D25: H | E25: 999911 | F25: Getting Needed Care | G25: 2 | H25: CAHPS | I25: =VLOOKUP(I$2&$E25, 'Data for Analysis'!$A:$P,16,0) -> 5
A26: N | B26: D | C26: N | D26: H | E26: 999811 | F26: Getting Needed Prescription Drugs | G26: 2 | H26: CAHPS | I26: =VLOOKUP(I$2&$E26, 'Data for Analysis'!$A:$P,16,0) -> 3
A27: N | B27: D | C27: N | D27: H | E27: 999810 | F27: Rating of Drug Plan | G27: 2 | H27: CAHPS | I27: =VLOOKUP(I$2&$E27, 'Data for Analysis'!$A:$P,16,0) -> 1
A28: N | B28: C | C28: N | D28: H | E28: 999914 | F28: Rating of Health Care Quality | G28: 2 | H28: CAHPS | I28: =VLOOKUP(I$2&$E28, 'Data for Analysis'!$A:$P,16,0) -> 5
A29: N | B29: C | C29: N | D29: H | E29: 999915 | F29: Rating of Health Plan | G29: 2 | H29: CAHPS | I29: =VLOOKUP(I$2&$E29, 'Data for Analysis'!$A:$P,16,0) -> 3
A30: N | B30: C | C30: N | D30: H | E30: 909230 | F30: Breast Cancer Screening | G30: 1 | H30: HEDIS | I30: =VLOOKUP(I$2&$E30, 'Data for Analysis'!$A:$P,16,0) -> 2
A31: N | B31: C | C31: N | D31: H | E31: 107125 | F31: Care for Older Adults - Medication Review | G31: 1 | H31: HEDIS | I31: =VLOOKUP(I$2&$E31, 'Data for Analysis'!$A:$P,16,0) -> 5
A32: N | B32: C | C32: N | D32: H | E32: 107126 | F32: Care for Older Adults - Functional Status Assessment | G32: 1 | H32: HEDIS | I32: =VLOOKUP(I$2&$E32, 'Data for Analysis'!$A:$P,16,0) -> NR
